Workbook

Sheet 가이드
A1: M/H 산출 가이드
F2: 45838
A3: I. | B3: 각 시트(탭) 관련 안내
B5: 1. Summary 시트
C6: - 보고 시 활용하기 위해 'M/H 산출 Summary'를 나타낸 시트.
C7: - Input 시트의 '외주최소화 적용 유무' 선택과 연동되어, M/H Summary가 변경 적용 됨.
C8: - Input 시트와 Output1 시트와 연동되어 자동 산출 됨.
C9: - 입력항목: Sheet 상단에 확인하고자 하는 Case (Case1~3)를 선택 입력 필요.
B11: 2. 산출기준 시트
C12: - 표준 난이도별 Unit M/H와 도면 매수 산정 기준 등이 나와있는 M/H 산출기준에 대한 상세 및 설명 시트.
C13: - Input 시트의 '외주최소화 적용 유무' 선택에 따라, 난이도별 Unit M/H가 변경 적용 됨.
C14: - 입력항목: 없음
B16: 3. Input 시트
C17: - M/H 산출을 위한 필수 값들을 입력하는 Table. M/H 산출을 위한 Base 가 되는 Data 입력을 위한 시트.
C18: - 입력항목: '외주최소화 적용 유무', 'GEC 수행 비율', 'Item Q'ty' 및 'Project Codition' 등 다양한 Input을 입력.
B20: 4. OP1 시트 (Output1 시트)
C21: - Input 시트의 입력 값을 바탕으로, Case1~3의 내부/GEC/외부 M/H가 자동 산출되는 시트.
C22: - 내부 확인 및 검토 용으로 활용하기 위한 목적으로 동시에 Case 1~3를 모두 확인 가능.
C23: - 입력항목: 없음
B25: 5. OP2-1 시트 (Output2-1 시트)
C26: - Output1 시트 내용 중 Case1 (외주-단종 Case) 의 산출 M/H에 대한 보고서 형식의 시트.
C27: - Input 시트와 Output1 시트와 연동되어 자동 산출 됨.
C28: - 입력항목: 없음
B30: 6. OP2-2 시트 (Output2-2 시트)
C31: - Output1 시트 내용 중 Case2 (GEC & 외주-단종 Case) 의 산출 M/H에 대한 보고서 형식의 시트.
C32: - Input 시트와 Output1 시트와 연동되어 자동 산출 됨.
C33: - 입력항목: 없음
B35: 7. OP2-3 시트 (Output2-3 시트)
C36: - Output1 시트 내용 중 Case3 (GEC & 외주-종합 Case) 의 산출 M/H에 대한 보고서 형식의 시트.
C37: - Input 시트와 Output1 시트와 연동되어 자동 산출 됨.
C38: - 입력항목: 없음
A40: II. | B40: 각 케이스 관련 안내
B42: 1. Case1 (외주-단종 Case)
C43: - GEC 참여 없이, HEC와 '외주-단종사'만 수행하는 Case
C44: - '외주-단종사'는 내부업무 수행 불가
B46: 2. Case2 (GEC & 외주-단종 Case)
C47: - HEC, GEC & '외주-단종사'가 함께 수행하는 Case
C48: - '외주-단종사'는 내부업무 수행 불가, GEC는 내부/외부업무 모두 일부 수행 가능
C49: - GEC의 내부/외부 업무 수행 비율은 프로젝트별 별도 협의 필요
B51: 3. Case3 (GEC & 외주-종합 Case)
...

Sheet Summary
B1: Case | C1: Summary Case Selection | P1: Case1. 외주-단종 Case
B2: C&I설계기준 | C2: Case1. 외주-단종 Case | E2: <= Case Selection 필요 | P2: Case2. GEC + 외주-단종 Case | Q2: 외주-단종
B3: 통신설계기준 | C3: Case1. 외주-단종 Case | E3: <= Case Selection 필요 | P3: Case3. GEC + 외주-종합 Case | Q3: 외주-종합
B5: 실행사업 M/H Summary (C&I + 통신)
B7: =Input_CI!B5 -> PROJECT: Promigas CPF Project | H7: =Input_CI!AK5 -> 46255
B9: 1. M/H Summary:
B10: 구분 | C10: 합계
C11: 내부 | D11: GEC | E11: 외주
B12: M/H | C12: =C21+F21 -> 21120.8 | D12: =D21+G21 -> 0 | E12: =E21+H21 -> 13863
B13: M/M | C13: =C22+F22 -> 129.44102 | D13: =D22+G22 -> 0 | E13: =E22+H22 -> 84.939846
B14: 투입 인원 | C14: =C23+F23 -> 15.723605 | D14: =D23+G23 -> 0 | E14: =E23+H23 -> 10.24654
B16: 2. M/H 상세내역:
B17: 구분 | C17: C&I설계 Part | F17: 통신설계 Part
C18: =C2 -> Case1. 외주-단종 Case | F18: =C2 -> Case1. 외주-단종 Case
C19: =산출기준_CI!A5 -> 일반 Ver. | F19: =산출기준_TEL!A5 -> 일반 Ver.
C20: 내부 | D20: GEC | E20: =IF(C2=P3,Q3,Q2) -> 외주-단종 | F20: 내부 | G20: GEC | H20: =IF(C3=P3,Q3,Q2) -> 외주-단종
B21: M/H | C21: =IF(C2=P1,OP1_CI!J128,IF(Summary!C2=Summary!P2,OP1_CI!L128,IF(Summary!C2=Summary!P3,OP1_CI!N128))) -> 11582.8 | D21: =IF(C2=P1,0,OP1_CI!P128) -> 0 | E21: =IF(C2=P1,OP1_CI!V128,IF(Summary!C2=Summary!P2,OP1_CI!X128,IF(Summary!C2=Summary!P3,OP1_CI!Z128))) -> 7742 | F21: =IF(C3=P1,OP1_TEL!J113,IF(C3= P2,OP1_TEL!L113,IF(C3=P3,OP1_TEL!N113))) -> 9538 | G21: =IF(C3=P1,0,OP1_TEL!P113) -> 0 | H21: =IF(C3=P1,OP1_TEL!V113,IF(C3= P2,OP1_TEL!X113,IF(C3=P3,OP1_TEL!Z113))) -> 6121
B22: M/M | C22: =IF(C2=P1,OP1_CI!J129,IF(Summary!C2=Summary!P2,OP1_CI!L129,IF(Summary!C2=Summary!P3,OP1_CI!N129))) -> 70.198788 | D22: =IF(C2=P1,0,OP1_CI!P129) -> 0 | E22: =IF(C2=P1,OP1_CI!V129,IF(Summary!C2=Summary!P2,OP1_CI!X129,IF(Summary!C2=Summary!P3,OP1_CI!Z129))) -> 46.921212 | F22: =IF(C3=P1,OP1_TEL!J114,IF(C3= P2,OP1_TEL!L114,IF(C3=P3,OP1_TEL!N114))) -> 59.242236 | G22: =IF(C3=P1,0,OP1_TEL!P114) -> 0 | H22: =IF(C3=P1,OP1_TEL!V114,IF(C3= P2,OP1_TEL!X114,IF(C3=P3,OP1_TEL!Z114))) -> 38.018634
B23: 투입 인원 | C23: =IF(C2=P1,OP1_CI!J130,IF(Summary!C2=Summary!P2,OP1_CI!L130,IF(Summary!C2=Summary!P3,OP1_CI!N130))) -> 5.849899 | D23: =IF(C2=P1,0,OP1_CI!P130) -> 0 | E23: =IF(C2=P1,OP1_CI!V130,IF(Summary!C2=Summary!P2,OP1_CI!X130,IF(Summary!C2=Summary!P3,OP1_CI!Z130))) -> 3.910101 | F23: =IF(C3=P1,OP1_TEL!J115,IF(C3= P2,OP1_TEL!L115,IF(C3=P3,OP1_TEL!N115))) -> 9.873706 | G23: =IF(C3=P1,0,OP1_TEL!P115) -> 0 | H23: =IF(C3=P1,OP1_TEL!V115,IF(C3= P2,OP1_TEL!X115,IF(C3=P3,OP1_TEL!Z115))) -> 6.3364389

Sheet 산출기준_CI
A1: C&I설계 화공 실행사업 MH 산출기준 (Rev.3) | R1: 산출기준_수정금지
A3: 산출기준 적용 Version (일반 vs 외주최소화 Ver.) | E3: Notes
E4: 1. | F4: 개별성과품 난이도가 정의되어 있지 않은 경우, Unit M/H 난이도 '상, 중, 하'는 PJT 특성 (발주처 성향, PMC 개입여부, 승인 Level 및 절차 등) 및 Condition 등을 고려 결정 | O4: 외주최소화 적용 유무에 따라 달라지는 값
A5: =IF(Input_CI!E3="Yes", "외주최소화 Ver.", "일반 Ver.") -> 일반 Ver. | F5: - 난이도 결정 상세는 Input탭의 'Project Condition & Information (C)항'을 참고 | O5: 외추최소화 적용 유무와 상관없이 유지되는 값
E6: 2. | F6: Revamping등 특이한 Case는 난이도를 N/A로 처리하고 산출기준과는 관례없이 현실에 맞는 M/H를 적용
P7: 45838 | R7: Rev.3
A8: NO. | B8: Activity | D8: 단위 | E8: 난이도별 Unit M/H | M8: 내부/외부 MAN HOUR 산출 지침 및 Drawing상 반영되야 할 Min. requirement | N8: MAN-HOUR 산출 지침
E9: 내부 Unit M/H | I9: 외부 Unit M/H | N9: Scale | O9: 역무 | P9: 도면 매수 산정 Guide
E10: SPI | F10: 상 | G10: 중 | H10: 하 | I10: SPI | J10: 상 | K10: 중 | L10: 하
A12: G | B12: GENERAL
A13: 1 | B13: 마일스톤 연계 미팅 / Workshop
B14: 1) | C14: Meeting & Coordination | D14: Lot | E14: - | F14: 120 | G14: 90 | H14: 45 | I14: - | J14: - | K14: - | L14: - | M14: LE 미팅, 설계 정보 전달, 인허가 Support 등 | P14: 난이도 "중" 기준 60 M/H 고려 | R14: 통신과 함께 MH 조정 (통신 축소 / CI 확대)
B15: 2) | C15: Design Review (30%, 60%, 90%) | D15: Lot | E15: - | F15: 180 | G15: 120 | H15: 60 | I15: - | J15: - | K15: - | L15: - | M15: 각 단계별 Design Review 참석 | P15: 난이도 "중" 기준 Instrument Review 시 10 Working Day 참석 (30% : 2일, 60% : 4일, 90% : 4일) | R15: 통신과 함께 MH 조정 (통신 축소 / CI 확대)
B16: 3) | C16: Workshop (ITB, Package, VELL) | D16: Lot | E16: - | F16: 80 | G16: 60 | H16: 30 | I16: - | J16: - | K16: - | L16: - | M16: ITB Workshop, Package Workshop, VELL Workshop 등 준비 및 참석 | P16: 난이도 "중" 기준 60 M/H 고려 | R16: NEW, Key Information for Package 작성 포함 // 일반적으로 GEC 역무 없음
A18: 2 | B18: ITB Review / FEED Verification / CER
B19: 1) | C19: ITB Review & Interface work. | D19: Lot | E19: - | F19: 340 | G19: 220 | H19: 120 | I19: - | J19: - | K19: - | L19: - | M19: ITB Review & Workshop, 입찰/실행 인수인계, MDR/MSR 작성, JV/Consortium 업무, W/G(UG, Module 등) | N19: N/A | O19: 설계 | P19: 난이도 "중" 기준 220 M/H 고려 | R19: 통신과 함께 MH 조정 (통신 축소 / CI 확대)
B20: 2) | C20: 발주처 협의 (Technical Clarification) | D20: 명 | E20: - | F20: 80 | G20: 60 | H20: 30 | I20: - | J20: - | K20: - | L20: - | M20: VE제안, Letter/TQ 작성, Technical Support | P20: 난이도 "중" 기준 프로젝트 수행 초기 2개월 (10명 x 1.5MH/Day)
B21: 3) | C21: Feed Verification | D21: 명 | E21: - | F21: 80 | G21: 60 | H21: 30 | I21: - | J21: - | K21: - | L21: - | M21: FEED 문서 검토 및 Clarification | P21: 난이도 "중" 기준프로젝트 수행 초기 2개월 (10명 x 1.5MH/Day)
B22: 4) | C22: Early Work | D22: 명 | E22: - | F22: 400 | G22: 320 | H22: 150 | I22: - | J22: - | K22: - | L22: - | M22: Package 업무 Support, IO Summary 작성, MR Draft 작성 (ICSS, Valve) | P22: 난이도 "중" 기준프로젝트 수행 초기 2개월 (4명 x 8MH/Day)
B23: 5) | C23: Cold Eye Review (Project Team) | D23: 명 | E23: - | F23: 16 | G23: 12 | H23: 8 | I23: - | J23: - | K23: - | L23: - | M23: CER W/G에서 작성한 Comment에 대한 검토 및 조치 | R23: NEW, 본사 CER W/G의 검토 역무는 MH에 미포함 됨. 포함 방안 검토 협의 필요
A25: E | B25: ENGINEERING (설계 관련)
A26: 1 | B26: Design Basis / Specification
B27: 1) | C27: Technical Specification
C28: - Control System | D28: Set | E28: - | F28: 200 | G28: 120 | H28: 60 | I28: - | J28: - | K28: - | L28: - | M28: 1) 난이도 산정기준 - 상 : New Generation - 중 : Feed 에 포함되어 Minor Modification or Updating - 하 : HEC Standard Specification 적용. | N28: N/A | O28: 설계
C29: - Packaged Instrument (Metering, Analzyer, TGS & etc.) | D29: Set | E29: - | F29: 140 | G29: 70 | H29: 40 | I29: - | J29: - | K29: - | L29: - | N29: N/A | O29: 설계
C30: - Field Instrument | D30: Set | E30: - | F30: 70 | G30: 35 | H30: 20 | I30: - | J30: - | K30: - | L30: - | N30: N/A | O30: 설계
C31: - Others | D31: Set | E31: - | F31: 70 | G31: 35 | H31: 20 | I31: - | J31: - | K31: - | L31: - | N31: N/A | O31: 설계
B32: 2) | C32: Design Basis 작성 | D32: Lot | F32: 340 | G32: 230 | H32: 160 | I32: - | J32: - | K32: - | L32: - | M32: LE업무지침서 9항에 따라 Specification Summary, Material Selection table, Cable/JB/Tray application table, cable gland selection table 등 설계 기준 작성 | N32: N/A | O32: 설계 | P32: LE업무지침서 9항에 따라 Specification Summary, Material Selection table, Cable/JB/Tray application table, cable gland selection table 등 설계 기준 작성
A34: 2 | B34: Summary / List / Table
B35: 1) | C35: Instrument Index | D35: Ea | E35: =IF(A5="일반 Ver.", 0.7, 0.8) -> 0.7 | F35: - | G35: =IF(A5="일반 Ver.", 0.5, 0.6) -> 0.5 | H35: - | I35: 0.2 | J35: - | K35: =IF(A5="일반 Ver.", 0.1, 0) -> 0.1 | L35: - | M35: 1) Tag no., Loop no. Inst. Type, P&ID no., Service, Equip./Line no., Location, System, I/O type 2) Data sheet no., JB connection dwg no., Hook-up dwg no., Loop dwg no. (Project 마다 input 항목 달라질 수 있슴 ) | N35: None | O35: 설계 | P35: 1) All Instrument & F&G 계기수량의 합 * 기계 Package Index는 발주처 요구시 PKG Vendor의 Native Index file을 접수하여 Master Index에 반영
B36: 2) | C36: ICSS IO database (IODB) | D36: Point | E36: =IF(A5="일반 Ver.", 0.5, 0.6) -> 0.5 | F36: - | G36: =IF(A5="일반 Ver.", 0.3, 0.4) -> 0.3 | H36: - | I36: 0.3 | J36: - | K36: =IF(A5="일반 Ver.", 0.1, 0) -> 0.1 | L36: - | M36: 1) Tag no., Loop no. Inst. Type, P&ID no., Service, System, I/O type은 Inst Index를 활용 Alarm set, Range등은 HEC에서 기입 (HEC내부 역무) 2) JB no., JB TB no., Marshalling TB. No, Package Panel TB no, No. IRP TB no기입 3) Secondary & Multi cable no. wire identification 정보 입력 | N36: None | O36: 설계 | P36: 1) Total ICSS (DCS+ESD+F&G)+MMS IO 수량
B37: 3) | C37: Instrument Cable Schedule | D37: A4 | E37: - | F37: =IF(A5="일반 Ver.", 0.3, 0.6) -> 0.3 | G37: =IF(A5="일반 Ver.", 0.3, 0.6) -> 0.3 | H37: =IF(A5="일반 Ver.", 0.3, 0.6) -> 0.3 | I37: - | J37: =IF(A5="일반 Ver.", 4, 3.7) -> 4 | K37: =IF(A5="일반 Ver.", 3, 2.7) -> 3 | L37: =IF(A5="일반 Ver.", 2, 1.7) -> 2 | M37: 1) Cable no, From/To, Cable code, Cable length 2) Cable gland spec. & q'ty 3) Drum number 4) JB 1개당 min. 1장 assign | N37: None | O37: 설계 / 제도 | P37: 1) HEC구매분 (PKG 제외) Junction box 수량 x 1.2배
B38: 4) | C38: UPS / Normal Power Load List | D38: Lot | E38: - | F38: - | G38: 50 | H38: - | I38: - | J38: - | K38: - | L38: - | M38: 타부서 Information 자료 | N38: None | O38: 설계 / 제도 | R38: to EL
B39: 5) | C39: Heat Dissipation List | D39: Lot | E39: - | F39: - | G39: 50 | H39: - | I39: - | J39: - | K39: - | L39: - | M39: 타부서 Information 자료 | N39: None | O39: 설계 / 제도 | R39: to HVAC
B40: 6) | C40: Electrical / Steam Tracing List | D40: Lot | E40: - | F40: - | G40: =IF(A5="일반 Ver.", 100, 120) -> 100 | H40: - | I40: - | J40: - | K40: =IF(A5="일반 Ver.", 100, 80) -> 100 | L40: - | M40: 타부서 Information 자료 | N40: None | O40: 설계 / 제도 | R40: to EL
B41: 7) | C41: 3D Library Data | D41: Ea | E41: - | F41: - | G41: 0.1 | H41: - | I41: - | J41: - | K41: - | L41: - | M41: 타부서 Information 자료 | N41: None | O41: 설계 / 제도 | P41: 1) All Valves, Flow & Level Instruments 수량의 합 | R41: to PI
B42: 8) | C42: Cable Tray/Duct Loading Data | D42: Lot | E42: - | F42: - | G42: =IF(A5="일반 Ver.", 50, 60) -> 50 | H42: - | I42: - | J42: - | K42: =IF(A5="일반 Ver.", 50, 40) -> 50 | L42: - | M42: 타부서 Information 자료 | N42: None | O42: 설계 / 제도 | R42: to PI & CV
B43: 9) | C43: Other 타부서 Information | D43: Lot | E43: - | F43: - | G43: =IF(A5="일반 Ver.", 50, 60) -> 50 | H43: - | I43: - | J43: - | K43: =IF(A5="일반 Ver.", 50, 40) -> 50 | L43: - | M43: 타부서 Information 자료 (Foundation Information, Building Opening Information, Field Grounding Information, UG Composite Drawing, Trench & Duct Bank Loading & etc.) | N43: None | O43: 설계 / 제도
A45: 3 | B45: Calculation
B46: 1) | C46: Weak Frequency Calculation for Thermowell | D46: Ea | E46: - | F46: - | G46: 0.5 | H46: - | I46: - | J46: - | K46: - | L46: - | M46: 별도 성과품을 제출하거나, 직접 수행하는 경우만 M/H 반영. 그 외 Vendor Data 로만 진행 시는 미반영. | N46: N/A | O46: 설계
...

Sheet Input_CI
B1: C&I Man Hour Key Factor Input Table (Rev.3) | AM1: INPUT
B2: KEY INPUT | I2: 필수 입력 항목
B3: 외주최소화 적용 유무 | E3: No | I3: 자동 산출 항목 | M3: 숨김처리 | N3: 숨김처리 | O3: 숨김처리 | P3: 숨김처리 | Q3: 숨김처리 | R3: 숨김처리
I4: GEC 입력 항목 | M4: 삭제 금지 | N4: 삭제 금지 | O4: 삭제 금지 | P4: 삭제 금지 | Q4: 삭제 금지 | R4: 삭제 금지 | AJ4: 삭제 금지
B5: PROJECT: Promigas CPF Project | AK5: 46255 | AM5: Rev.1
B6: Control & Instrumentation - Material, General & 인력지원 (A) | T6: Control & Instrumentation - Design, Deliverable & 내-외부 업무 수행 비율 (B) | AD6: Control & Instrumentation - Project Condition & Information (C)
B7: S/N | C7: Item (대분류) | D7: Item (중분류) | E7: Item 상세 (소분류) | F7: 내부 업무 중 GEC 수행 비율 (%) | G7: 내부 업무 중 외주-종합 수행 비율 (%) | H7: 외부 업무 중 GEC 수행 비율 (%) | I7: Quantity of Item | K7: Quantity of MR Set | M7: Material Requisition (Unit M/H) | N7: Material Requisition (Total M/H) | O7: Technical Bid Evaluation (Unit M/H) | P7: Technical Bid Evaluation (Total M/H) | Q7: Vendor Data Review (Unit M/H) | R7: Vendor Data Review (Total M/H) | S7: Note | T7: S/N | U7: Item (대분류) | V7: Item (중분류) | W7: Item 상세 (소분류) | X7: 내부 업무 중 GEC 수행 비율 (%) | Y7: 내부 업무 중 외주-종합 수행 비율 (%) | Z7: 외부 업무 중 GEC 수행 비율 (%) | AA7: Quantity | AC7: Note | AD7: S/N | AE7: Item (대분류) | AF7: Item (중분류) | AG7: Item 상세 (소분류) | AH7: 입력 | AI7: Factor | AJ7: 난이도 | AK7: Note
B8: A01 | C8: Control System | D8: Control System | E8: ICSS (DCS+ESD+F&G) | I8: 4300 | J8: Point | K8: 1 | L8: Set | M8: =IF(I8>0,산출기준_CI!G112,0) -> 120 | N8: =IF($K8>0, M8*K8, 0) -> 120 | O8: =IF(I8>0,산출기준_CI!G120,0) -> 400 | P8: =IF($K8>0, O8*K8, 0) -> 400 | Q8: =IF(I8=0,0,IF(I8<=2000,150,IF(I8>2000,ROUNDUP((150+(I8-2000)*0.04),0),fault))) -> 242 | R8: =IF($K8>0, Q8*K8, 0) -> 242 | T8: B01 | U8: Specification / Design Basis | V8: Technical Specification | W8: Control System | X8: 0.3 | Y8: 0.1 | AA8: 4 | AB8: Set | AD8: C01 | AE8: Project 표준 난이도 (General) | AF8: 발주처/PMC 성향, 난이도, 기술력 | AG8: 1) 국내 발주처 : 표준 M/H x 1.0 (증가 량 없음) | AH8: 8) | AI8: =IF(AH8="1)",1,IF(AH8="2)",1.05,IF(AH8="3)",1.1,IF(AH8="4)",1.15,IF(AH8="5)",1.2,IF(AH8="6)",1.25,IF(AH8="7)",1.15,IF(AH8="8)",1.2,"")))))))) -> 1.2 | AJ8: =IF(SUM(AI8:AI20)-2>1.19, "상", IF(SUM(AI8:AI20)-2>1.09, "중", IF(AI8>0.99-2,"하","ERROR"))) -> 상 | AK8: 발주처/PMC 성향 및 승인 절차 까다로움을 고려하여 난이도 Factor 1.0~1.25 (0~25%)를 표준 Man-Hour에 증가하거나, MH 산출기준 상에서 난이도 산정기준에 따라 선정된 난이도(상, 중, 하)에 따른 Unit MH를 적용한다.
B9: A02 | E9: ICSS + Pre-fabricated Building | I9: 0 | J9: Point | K9: 0 | L9: Set | M9: =IF(I9>0,산출기준_CI!F112,0) -> 0 | N9: =IF($K9>0, M9*K9, 0) -> 0 | O9: =IF(I9>0,산출기준_CI!F120,0) -> 0 | P9: =IF($K9>0, O9*K9, 0) -> 0 | Q9: =IF(I9=0,0,IF(I9<=2000,250,IF(I9>2000,ROUNDUP((250+(I9-2000)*0.04),0),fault))) -> 0 | R9: =IF($K9>0, Q9*K9, 0) -> 0 | T9: B02 | W9: Packaged Instrument (Metering, Analzyer, TGS & etc.) | X9: 0.3 | Y9: 0.1 | AA9: 3 | AB9: Set | AD9: C02 | AG9: 2) 국내 발주처(PMC가 있는 경우) : 표준 M/H x 1.05 (5% 증가)
B10: A03 | E10: Machinery Monitoring System | I10: 1000 | J10: Point | K10: 1 | L10: Set | M10: =IF(I10>0,120,0) -> 120 | N10: =IF($K10>0, M10*K10, 0) -> 120 | O10: =IF(I10>0,산출기준_CI!H120,0) -> 200 | P10: =IF($K10>0, O10*K10, 0) -> 200 | Q10: =IF(I10=0,0,IF(I10<=2000,150,IF(I10>2000,ROUNDUP((150+(I10-2000)*0.04),0),fault))) -> 150 | R10: =IF($K10>0, Q10*K10, 0) -> 150 | T10: B03 | W10: Field Instrument | X10: 0.3 | Y10: 0.1 | AA10: 1 | AB10: Set | AD10: C03 | AG10: 3) 동남아, 중앙아시아, 동유럽 국가 (PMC가 없는 경우): 표준 M/H x 1.1(10% 증가)
B11: A04 | E11: Other Control System | I11: 1000 | J11: Point | K11: 3 | L11: Set | M11: =IF(I11>0,산출기준_CI!G112,0) -> 120 | N11: =IF($K11>0, M11*K11, 0) -> 360 | O11: =IF(I11>0,산출기준_CI!H120,0) -> 200 | P11: =IF($K11>0, O11*K11, 0) -> 600 | Q11: =IF(I11=0,0,IF(I11<=2000,150,IF(I11>2000,ROUNDUP((150+(I11-2000)*0.04),0),fault))) -> 150 | R11: =IF($K11>0, Q11*K11, 0) -> 450 | S11: HIPS, Corrosion, SCS | T11: B04 | W11: Others | X11: 0.3 | Y11: 0.1 | AA11: 3 | AB11: Set | AD11: C04 | AG11: 4) 동남아, 중앙아시아, 동유럽 국가 (PMC가 있는 경우): 표준 M/H x 1.15(15% 증가)
B12: A05 | C12: Packaged Instrument | D12: Packaged Instrument | E12: Flow Metering System | I12: 4 | J12: Set | K12: 1 | L12: Set | M12: =IF(I12>0,산출기준_CI!$G$113,0) -> 85 | N12: =IF($K12>0, M12*K12, 0) -> 85 | O12: =MIN(350,IF(I12=0,0,IF(I12/K12<=2,200,IF(I12/K12>2,(200+((I12/K12-2)*20)),fault)))) -> 240 | P12: =IF($K12>0, O12*K12, 0) -> 240 | Q12: {=IF(I12=0,0,IF(I12/K12<=2,150,IF(I12/K12>2,(150+((I12/K12-2)*10)),fault)))} -> 170 | R12: =IF($K12>0, Q12*K12, 0) -> 170 | T12: B05 | V12: Design Basis | W12: Design Basis | X12: 0.3 | Y12: 0.1 | AA12: 1 | AB12: Lot | AD12: C05 | AG12: 5) 중동, 아프리카 국가 (PMC가 없는 경우): 표준 M/H x 1.2(20% 증가)
B13: A06 | E13: Analzyer System | I13: 13 | J13: Set | K13: 1 | L13: Set | M13: =IF(I13>0,산출기준_CI!$G$113,0) -> 85 | N13: =IF($K13>0, M13*K13, 0) -> 85 | O13: =MIN(350,IF(I13=0,0,IF(I13/K13<=2,200,IF(I13/K13>2,(200+((I13/K13-2)*20)),fault)))) -> 350 | P13: =IF($K13>0, O13*K13, 0) -> 350 | Q13: {=IF(I13=0,0,IF(I13/K13<=2,150,IF(I13/K13>2,(150+((I13/K13-2)*10)),fault)))} -> 260 | R13: =IF($K13>0, Q13*K13, 0) -> 260 | T13: B06 | U13: Summary / List / Table | V13: Instrument Index | W13: Instrument Index | X13: 0.3 | Y13: 0.1 | Z13: 0.3 | AA13: =SUM(I12:I42) -> 1539 | AB13: ea. | AC13: 외주 최소화 적용시 '내부 업무 중 외주-종합 수행 비율 (%)'은 0을 입력 할 것. | AD13: C06 | AG13: 6) 중동, 아프리카 국가 (PMC가 있을 경우): 표준 M/H x 1.25(25% 증가)
B14: A07 | E14: Ship Shore Link System | I14: 0 | J14: Set | K14: 0 | L14: Set | M14: =IF(I14>0,산출기준_CI!$G$113,0) -> 0 | N14: =IF($K14>0, M14*K14, 0) -> 0 | O14: =MIN(350,IF(I14=0,0,IF(I14/K14<=2,200,IF(I14/K14>2,(200+((I14/K14-2)*20)),fault)))) -> 0 | P14: =IF($K14>0, O14*K14, 0) -> 0 | Q14: {=IF(I14=0,0,IF(I14/K14<=2,150,IF(I14/K14>2,(150+((I14/K14-2)*10)),fault)))} -> 0 | R14: =IF($K14>0, Q14*K14, 0) -> 0 | T14: B07 | V14: ICSS IO database (IODB) | W14: ICSS IO database (IODB) | X14: 0.3 | Y14: 0.1 | Z14: 0.3 | AA14: =SUM(I8:I11) -> 6300 | AB14: ea. | AD14: C07 | AG14: 7) 기타 국가 (PMC가 없는 경우): 표준 M/H x 1.15(15% 증가)
B15: A08 | E15: Tank Gauging System | I15: 0 | J15: Set | K15: 0 | L15: Set | M15: =IF(I15>0,산출기준_CI!$G$113,0) -> 0 | N15: =IF($K15>0, M15*K15, 0) -> 0 | O15: =MIN(350,IF(I15=0,0,IF(I15/K15<=2,200,IF(I15/K15>2,(200+((I15/K15-2)*20)),fault)))) -> 0 | P15: =IF($K15>0, O15*K15, 0) -> 0 | Q15: =MIN(150,IF(I15=0,0,IF(I15/K15<=2,150,IF(I15/K15>2,(150+((I15/K15-2)*10)),fault)))) -> 0 | R15: =IF($K15>0, Q15*K15, 0) -> 0 | T15: B08 | V15: Instrument Cable Schedule | W15: Instrument Cable Schedule | X15: 0.3 | Y15: 0.1 | Z15: 0.3 | AA15: =ROUNDUP(I45*1.2,0) -> 720 | AB15: 장 | AD15: C08 | AG15: 8) 기타 국가 (PMC가 있는 경우): 표준 M/H x 1.2(20% 증가)
B16: A09 | E16: Fibre Optic Monitoring System | I16: 0 | J16: Set | K16: 0 | L16: Set | M16: =IF(I16>0,산출기준_CI!$G$113,0) -> 0 | N16: =IF($K16>0, M16*K16, 0) -> 0 | O16: =MIN(350,IF(I16=0,0,IF(I16/K16<=2,200,IF(I16/K16>2,(200+((I16/K16-2)*20)),fault)))) -> 0 | P16: =IF($K16>0, O16*K16, 0) -> 0 | Q16: =MIN(150,IF(I16=0,0,IF(I16/K16<=2,150,IF(I16/K16>2,(150+((I16/K16-2)*10)),fault)))) -> 0 | R16: =IF($K16>0, Q16*K16, 0) -> 0 | T16: B09 | V16: 타부서 Information | W16: UPS / Normal Power Load List | X16: 0.3 | Y16: 0.1 | AA16: 1 | AB16: Lot | AD16: C09 | AF16: Licensor Unit 포함 유무 | AG16: 1) Licensor 없음 : 표준 M/H x 1.0 (증가 량 없음) | AH16: 1) | AI16: =IF(AH16=0,"",IF(AH16="1)",1,IF(AH16=1,1,IF(AH16="2)",1.05,IF(AH16=2,1.05,IF(AH16="3)",1.1,IF(AH16=3,1.1,""))))))) -> 1 | AK16: Licensor Unit에 대한 추가 Requirement Study 및 상이한 Design Philosophy 적용에 대한 Work Volume 증가를 고려하여 난이도 Factor 1.0~1.1 (0~10%)를 표준 Man-Hour에 증가하거나, MH 산출기준 상에서 난이도 산정기준에 따라 선정된 난이도(상, 중, 하)에 따른 Unit MH를 적용한다.
B17: A10 | E17: Pipeline Leak Detection System | I17: 4 | J17: Set | K17: 1 | L17: Set | M17: =IF(I17>0,산출기준_CI!$G$113,0) -> 85 | N17: =IF($K17>0, M17*K17, 0) -> 85 | O17: =MIN(350,IF(I17=0,0,IF(I17/K17<=2,200,IF(I17/K17>2,(200+((I17/K17-2)*20)),fault)))) -> 240 | P17: =IF($K17>0, O17*K17, 0) -> 240 | Q17: =MIN(150,IF(I17=0,0,IF(I17/K17<=2,150,IF(I17/K17>2,(150+((I17/K17-2)*10)),fault)))) -> 150 | R17: =IF($K17>0, Q17*K17, 0) -> 150 | T17: B10 | W17: Heat Dissipation List | X17: 0.3 | Y17: 0.1 | AA17: 1 | AB17: Lot | AD17: C10 | AG17: 2) Case 1: 표준 M/H x 1.05 (5% 증가) *Licensor 1개인 경우
B18: A11 | E18: Air Quality Monitoring System | I18: 0 | J18: Set | K18: 0 | L18: Set | M18: =IF(I18>0,산출기준_CI!$G$113,0) -> 0 | N18: =IF($K18>0, M18*K18, 0) -> 0 | O18: =MIN(350,IF(I18=0,0,IF(I18/K18<=2,200,IF(I18/K18>2,(200+((I18/K18-2)*20)),fault)))) -> 0 | P18: =IF($K18>0, O18*K18, 0) -> 0 | Q18: =MIN(150,IF(I18=0,0,IF(I18/K18<=2,150,IF(I18/K18>2,(150+((I18/K18-2)*10)),fault)))) -> 0 | R18: =IF($K18>0, Q18*K18, 0) -> 0 | T18: B11 | W18: Electrical / Steam Tracing List | X18: 0.3 | Y18: 0.1 | Z18: 0.3 | AA18: 1 | AB18: Lot | AD18: C11 | AG18: 3) Case 2: 표준 M/H x 1.1 (10% 증가) *Licensor 2개 이상인 경우
B19: A12 | E19: Weather Monitoring System | I19: 0 | J19: Set | K19: 0 | L19: Set | M19: =IF(I19>0,산출기준_CI!$G$113,0) -> 0 | N19: =IF($K19>0, M19*K19, 0) -> 0 | O19: =MIN(350,IF(I19=0,0,IF(I19/K19<=2,200,IF(I19/K19>2,(200+((I19/K19-2)*20)),fault)))) -> 0 | P19: =IF($K19>0, O19*K19, 0) -> 0 | Q19: =MIN(150,IF(I19=0,0,IF(I19/K19<=2,150,IF(I19/K19>2,(150+((I19/K19-2)*10)),fault)))) -> 0 | R19: =IF($K19>0, Q19*K19, 0) -> 0 | T19: B12 | W19: 3D Library Data | X19: 0.3 | Y19: 0.1 | Z19: 0.3 | AA19: =SUM(I21:I31,I35:I37) -> 555 | AB19: Lot | AD19: C12 | AF19: Project 수행 Condition 고려 | AG19: 1) JV / Consortium 사업 유무 (HEC가 계장팀 Leading이 아닐 경우): 표준 M/H x 1.10 (10% 증가) | AH19: No | AI19: =1+IF(AH19="No",0,IF(AH19="Yes",0.1,0))+IF(AH20="No",0,IF(AH20="Yes",0.15,0)) -> 1 | AK19: Project 수행 Condition 에 따라 난이도 Factor 1.0~1.15 (0~15%)를 표준 Man-Hour에 증가하거나, MH 산출기준 상에서 난이도 산정기준에 따라 선정된 난이도(상, 중, 하)에 따른 Unit MH를 적용한다.
B20: A13 | E20: Other Package System | I20: 0 | J20: Set | K20: 0 | L20: Set | M20: =IF(I20>0,산출기준_CI!$G$113,0) -> 0 | N20: =IF($K20>0, M20*K20, 0) -> 0 | O20: =MIN(350,IF(I20=0,0,IF(I20/K20<=2,200,IF(I20/K20>2,(200+((I20/K20-2)*20)),fault)))) -> 0 | P20: =IF($K20>0, O20*K20, 0) -> 0 | Q20: =MIN(150,IF(I20=0,0,IF(I20/K20<=2,150,IF(I20/K20>2,(150+((I20/K20-2)*10)),fault)))) -> 0 | R20: =IF($K20>0, Q20*K20, 0) -> 0 | T20: B13 | W20: Cable Tray/Duct Loading Data | X20: 0.3 | Y20: 0.1 | Z20: 0.3 | AA20: 1 | AB20: Lot | AD20: C13 | AG20: 2) JV / Consortium 사업 유무 (HEC가 계장팀 Leading인 경우): 표준 M/H x 1.15 (15% 증가) | AH20: No
B21: A14 | C21: Tagged Valves | D21: Tagged Valves | E21: Control Valve + Self-regulating Valve | I21: 92 | J21: ea. | K21: 1 | L21: Set | M21: =IF(I21>0,산출기준_CI!$G$114,0) -> 60 | N21: =IF($K21>0, M21*K21, 0) -> 60 | O21: =IF(I21=0,0,IF(I21/K21<=100,180,IF(I21/K21>100,ROUNDUP((180+((I21/K21-100)*0.3)),0),fault))) -> 180 | P21: =IF($K21>0, O21*K21, 0) -> 180 | Q21: =IF(I21=0,0,IF(I21/K21<=100,100,IF(I21/K21>100,ROUNDUP((100+((I21/K21-100)*0.3)),0),fault))) -> 100 | R21: =IF($K21>0, Q21*K21, 0) -> 100 | T21: B14 | W21: Other 타부서 Information | X21: 0.3 | Y21: 0.1 | Z21: 0.3 | AA21: 1 | AB21: Lot | AD21: C14 | AE21: Design Basis / Specification 난이도 | AF21: Control System | AG21: 1) New Generation | AH21: 2) | AJ21: =IF(AH21="1)","상",IF(AH21="2)","중",IF(AH21="3)","하","ERROR"))) -> 중
B22: A15 | E22: Self-regulating Valve | I22: 0 | J22: ea. | K22: 0 | L22: Set | M22: =IF(I22>0,산출기준_CI!$G$114,0) -> 0 | N22: =IF($K22>0, M22*K22, 0) -> 0 | O22: =IF(I22=0,0,IF(I22/K22<=100,180,IF(I22/K22>100,ROUNDUP((180+((I22/K22-100)*0.3)),0),fault))) -> 0 | P22: =IF($K22>0, O22*K22, 0) -> 0 | Q22: =IF(I22=0,0,IF(I22/K22<=100,100,IF(I22/K22>100,ROUNDUP((100+((I22/K22-100)*0.3)),0),fault))) -> 0 | R22: =IF($K22>0, Q22*K22, 0) -> 0 | T22: B15 | U22: Calculation | V22: Weak Frequency Calculation for Thermowell | W22: On-line Thermowell 수량 | X22: 0.3 | Y22: 0.1 | AA22: 0 | AB22: ea. | AC22: 대상 Item Q'ty | AD22: C15 | AG22: 2) Feed 에 포함되어 Minor Modification or Updating
B23: A16 | E23: On-Off Valve | I23: 131 | J23: ea. | K23: 1 | L23: Set | M23: =IF(I23>0,산출기준_CI!$G$114,0) -> 60 | N23: =IF($K23>0, M23*K23, 0) -> 60 | O23: =IF(I23=0,0,IF(I23/K23<=100,180,IF(I23/K23>100,ROUNDUP((180+((I23/K23-100)*0.3)),0),fault))) -> 190 | P23: =IF($K23>0, O23*K23, 0) -> 190 | Q23: =IF(I23=0,0,IF(I23/K23<=100,100,IF(I23/K23>100,ROUNDUP((100+((I23/K23-100)*0.3)),0),fault))) -> 110 | R23: =IF($K23>0, Q23*K23, 0) -> 110 | T23: B16 | V23: Cv (Valve Coefficient) Calculation for Sizing | W23: Cv (Valve Coefficient) Calculation for Sizing | X23: 0.3 | Y23: 0.1 | AA23: 0 | AB23: ea. | AC23: 대상 Item Q'ty | AD23: C16 | AG23: 3) HEC Standard Specification 적용
B24: A17 | E24: Motor Operated Valve | I24: 7 | J24: ea. | K24: 1 | L24: Set | M24: =IF(I24>0,산출기준_CI!$G$114,0) -> 60 | N24: =IF($K24>0, M24*K24, 0) -> 60 | O24: =IF(I24=0,0,IF(I24/K24<=100,180,IF(I24/K24>100,ROUNDUP((180+((I24/K24-100)*0.3)),0),fault))) -> 180 | P24: =IF($K24>0, O24*K24, 0) -> 180 | Q24: =IF(I24=0,0,IF(I24/K24<=100,100,IF(I24/K24>100,ROUNDUP((100+((I24/K24-100)*0.3)),0),fault))) -> 100 | R24: =IF($K24>0, Q24*K24, 0) -> 100 | T24: B17 | V24: PSV Orificice Calculation for Sizing | W24: PSV Orificice Calculation for Sizing | X24: 0.3 | Y24: 0.1 | AA24: 0 | AB24: ea. | AC24: 대상 Item Q'ty | AD24: C17 | AF24: Packaged Instrument | AG24: 1) New Generation | AH24: 2) | AJ24: =IF(AH24="1)","상",IF(AH24="2)","중",IF(AH24="3)","하","ERROR"))) -> 중
B25: A18 | E25: HIPPS Valve | I25: 2 | J25: ea. | K25: 0 | L25: Set | M25: =IF(I25>0,산출기준_CI!$G$114,0) -> 60 | N25: =IF($K25>0, M25*K25, 0) -> 0 | O25: =IF(I25=0,0,IF(I25/K25<=100,180,IF(I25/K25>100,ROUNDUP((180+((I25/K25-100)*0.3)),0),fault))) -> #DIV/0! | P25: =IF($K25>0, O25*K25, 0) -> 0 | Q25: =IF(I25=0,0,IF(I25/K25<=100,100,IF(I25/K25>100,ROUNDUP((100+((I25/K25-100)*0.3)),0),fault))) -> #DIV/0! | R25: =IF($K25>0, Q25*K25, 0) -> 0 | T25: B18 | V25: Flow Element Calculation | W25: Flow Element Calculation | X25: 0.3 | Y25: 0.1 | AA25: 0 | AB25: ea. | AC25: 대상 Item Q'ty | AD25: C18 | AG25: 2) Feed 에 포함되어 Minor Modification or Updating
B26: A19 | E26: Safety Relief Valve | I26: 99 | J26: ea. | K26: 1 | L26: Set | M26: =IF(I26>0,산출기준_CI!$G$114,0) -> 60 | N26: =IF($K26>0, M26*K26, 0) -> 60 | O26: =IF(I26=0,0,IF(I26/K26<=100,180,IF(I26/K26>100,ROUNDUP((180+((I26/K26-100)*0.3)),0),fault))) -> 180 | P26: =IF($K26>0, O26*K26, 0) -> 180 | Q26: =IF(I26=0,0,IF(I26/K26<=100,100,IF(I26/K26>100,ROUNDUP((100+((I26/K26-100)*0.3)),0),fault))) -> 100 | R26: =IF($K26>0, Q26*K26, 0) -> 100 | T26: B19 | U26: Study / Analysis | V26: SIL or IPF Calculation, SRS | W26: SIL or IPF Calculation, Safety Requirement Specification (SRS) | X26: 0.3 | Y26: 0.1 | AA26: 200 | AB26: ea. | AC26: 대상 Item Q'ty | AD26: C19 | AG26: 3) HEC Standard Specification 적용
B27: A20 | E27: Rupture Disc | I27: 0 | J27: ea. | K27: 0 | L27: Set | M27: =IF(I27>0,산출기준_CI!$G$114,0) -> 0 | N27: =IF($K27>0, M27*K27, 0) -> 0 | O27: =IF(I27=0,0,IF(I27/K27<=100,180,IF(I27/K27>100,ROUNDUP((180+((I27/K27-100)*0.3)),0),fault))) -> 0 | P27: =IF($K27>0, O27*K27, 0) -> 0 | Q27: =IF(I27=0,0,IF(I27/K27<=100,100,IF(I27/K27>100,ROUNDUP((100+((I27/K27-100)*0.3)),0),fault))) -> 0 | R27: =IF($K27>0, Q27*K27, 0) -> 0 | T27: B20 | V27: Instrinsical Safety Entity Calculation | W27: Intrinsic Safety Entity Calculation | X27: 0.3 | Y27: 0.1 | AA27: 0 | AB27: ea. | AC27: 대상 Item Q'ty | AD27: C20 | AF27: Field Instrument | AG27: 1) New Generation | AH27: 2) | AJ27: =IF(AH27="1)","상",IF(AH27="2)","중",IF(AH27="3)","하","ERROR"))) -> 중
B28: A21 | E28: Deluge Valve | I28: 25 | J28: ea. | K28: 1 | L28: Set | M28: =IF(I28>0,산출기준_CI!$G$114,0) -> 60 | N28: =IF($K28>0, M28*K28, 0) -> 60 | O28: =IF(I28=0,0,IF(I28/K28<=100,180,IF(I28/K28>100,ROUNDUP((180+((I28/K28-100)*0.3)),0),fault))) -> 180 | P28: =IF($K28>0, O28*K28, 0) -> 180 | Q28: =IF(I28=0,0,IF(I28/K28<=100,100,IF(I28/K28>100,ROUNDUP((100+((I28/K28-100)*0.3)),0),fault))) -> 100 | R28: =IF($K28>0, Q28*K28, 0) -> 100 | T28: B21 | V28: FF Entity Caculation for Segment Design | W28: FF Entity Caculation for Segment Design | X28: 0.3 | Y28: 0.1 | AA28: 0 | AB28: ea. | AC28: 대상 Item Q'ty | AD28: C21 | AG28: 2) Feed 에 포함되어 Minor Modification or Updating
B29: A22 | E29: Other Tagged Valve | I29: 0 | J29: ea. | K29: 0 | L29: Set | M29: =IF(I29>0,산출기준_CI!$G$114,0) -> 0 | N29: =IF($K29>0, M29*K29, 0) -> 0 | O29: =IF(I29=0,0,IF(I29/K29<=100,180,IF(I29/K29>100,ROUNDUP((180+((I29/K29-100)*0.3)),0),fault))) -> 0 | P29: =IF($K29>0, O29*K29, 0) -> 0 | Q29: =IF(I29=0,0,IF(I29/K29<=100,100,IF(I29/K29>100,ROUNDUP((100+((I29/K29-100)*0.3)),0),fault))) -> 0 | R29: =IF($K29>0, Q29*K29, 0) -> 0 | T29: B22 | U29: Drawing | V29: Control System Architecture | W29: Control System Configuration | X29: 0.3 | Y29: 0.1 | Z29: 0.3 | AA29: 3 | AB29: 장 | AD29: C22 | AG29: 3) HEC Standard Specification 적용
B30: A23 | C30: Tagged Instrument | D30: Electronic Instrument | E30: Flow Instrument | I30: 10 | J30: ea. | K30: 1 | L30: Set | M30: =IF(I30>0,산출기준_CI!$G$115,0) -> 60 | N30: =IF($K30>0, M30*K30, 0) -> 60 | O30: =IF(I30=0,0,IF(I30/K30<=200,120,IF(I30/K30>200,ROUNDUP((120+((I30/K30-200)*0.1)),0),fault))) -> 120 | P30: =IF($K30>0, O30*K30, 0) -> 120 | Q30: =IF(I30=0,0,IF(I30/K30<=200,50,IF(I30/K30>200,ROUNDUP((50+((I30/K30-200)*0.1)),0),fault))) -> 50 | R30: =IF($K30>0, Q30*K30, 0) -> 50 | T30: B23 | W30: Inst Earthing philosophy (if req'd) | X30: 0.3 | Y30: 0.1 | Z30: 0.3 | AA30: 2 | AB30: 장 | AD30: C23 | AF30: Others | AG30: 1) New Generation | AH30: 2) | AJ30: =IF(AH30="1)","상",IF(AH30="2)","중",IF(AH30="3)","하","ERROR"))) -> 중
B31: A24 | E31: Level Instrument | I31: 18 | J31: ea. | K31: 2 | L31: Set | M31: =IF(I31>0,산출기준_CI!$G$115,0) -> 60 | N31: =IF($K31>0, M31*K31, 0) -> 120 | O31: =IF(I31=0,0,IF(I31/K31<=200,120,IF(I31/K31>200,ROUNDUP((120+((I31/K31-200)*0.1)),0),fault))) -> 120 | P31: =IF($K31>0, O31*K31, 0) -> 240 | Q31: =IF(I31=0,0,IF(I31/K31<=200,50,IF(I31/K31>200,ROUNDUP((50+((I31/K31-200)*0.1)),0),fault))) -> 50 | R31: =IF($K31>0, Q31*K31, 0) -> 100 | T31: B24 | V31: Layout Drawings | W31: Instrument Key Plan for Layout Drawings | X31: 0.3 | Y31: 0.1 | Z31: 0.3 | AA31: =IF(AA33>0,1,0)+IF(AA34>0,1,0)+IF(AA35>0,1,0)+IF(AA36>0,1,0)+IF(AA37>0,1,0)+IF(AA38>0,1,0) -> 6 | AB31: 장 | AD31: C24 | AG31: 2) Feed 에 포함되어 Minor Modification or Updating
B32: A25 | E32: Field Transmitter (PT, TT, DPT & Indicator) | I32: 521 | J32: ea. | K32: 1 | L32: Set | M32: =IF(I32>0,산출기준_CI!$G$115,0) -> 60 | N32: =IF($K32>0, M32*K32, 0) -> 60 | O32: =IF(I32=0,0,IF(I32/K32<=200,120,IF(I32/K32>200,ROUNDUP((120+((I32/K32-200)*0.1)),0),fault))) -> 153 | P32: =IF($K32>0, O32*K32, 0) -> 153 | Q32: =IF(I32=0,0,IF(I32/K32<=200,50,IF(I32/K32>200,ROUNDUP((50+((I32/K32-200)*0.1)),0),fault))) -> 83 | R32: =IF($K32>0, Q32*K32, 0) -> 83 | T32: B25 | W32: Symbol & Legends for Inst. Layout Drawings | X32: 0.3 | Y32: 0.1 | Z32: 0.3 | AA32: 2 | AB32: 장 | AC32: 최대 2장 | AD32: C25 | AG32: 3) HEC Standard Specification 적용
B33: A26 | E33: Load Cell Transmitter | I33: 0 | J33: ea. | K33: 0 | L33: Set | M33: =IF(I33>0,산출기준_CI!$G$115,0) -> 0 | N33: =IF($K33>0, M33*K33, 0) -> 0 | O33: =IF(I33=0,0,IF(I33/K33<=200,120,IF(I33/K33>200,ROUNDUP((120+((I33/K33-200)*0.1)),0),fault))) -> 0 | P33: =IF($K33>0, O33*K33, 0) -> 0 | Q33: =IF(I33=0,0,IF(I33/K33<=200,50,IF(I33/K33>200,ROUNDUP((50+((I33/K33-200)*0.1)),0),fault))) -> 0 | R33: =IF($K33>0, Q33*K33, 0) -> 0 | T33: B26 | W33: Instrument Location Plan | X33: 0.3 | Y33: 0.1 | Z33: 0.3 | AA33: =ROUNDUP(SUM(I12:I39)/50,0) -> 23 | AB33: 장 | AD33: C26 | AF33: Design Basis | AG33: Design Basis | AH33: 자동생성 | AJ33: =$AJ$8 -> 상 | AK33: Project 표준 난이도 적용
B34: A27 | E34: Other Electronic Instrument | I34: 0 | J34: ea. | K34: 0 | L34: Set | M34: =IF(I34>0,산출기준_CI!$G$115,0) -> 0 | N34: =IF($K34>0, M34*K34, 0) -> 0 | O34: =IF(I34=0,0,IF(I34/K34<=200,120,IF(I34/K34>200,ROUNDUP((120+((I34/K34-200)*0.1)),0),fault))) -> 0 | P34: =IF($K34>0, O34*K34, 0) -> 0 | Q34: =IF(I34=0,0,IF(I34/K34<=200,50,IF(I34/K34>200,ROUNDUP((50+((I34/K34-200)*0.1)),0),fault))) -> 0 | R34: =IF($K34>0, Q34*K34, 0) -> 0 | T34: B27 | W34: Main Cable Routing layout | X34: 0.3 | Y34: 0.1 | Z34: 0.3 | AA34: =ROUNDUP(AA36*0.7,0) -> 24 | AB34: 장 | AD34: C27 | AE34: Summary / List / Table 난이도 | AF34: Instrument Index | AG34: 1) SPI 적용-내부 | AH34: 2) | AJ34: =IF(AH34="1)","SPI-내부",IF(AH34="2)","SPI-외부",IF(AH34="3)","중","ERROR"))) -> SPI-외부
B35: A28 | D35: Non-Electronic Instrument | E35: Flow Element | I35: 134 | J35: ea. | K35: 1 | L35: Set | M35: =IF(I35>0,산출기준_CI!$G$115,0) -> 60 | N35: =IF($K35>0, M35*K35, 0) -> 60 | O35: =IF(I35=0,0,IF(I35/K35<=200,120,IF(I35/K35>200,ROUNDUP((120+((I35/K35-200)*0.1)),0),fault))) -> 120 | P35: =IF($K35>0, O35*K35, 0) -> 120 | Q35: =IF(I35=0,0,IF(I35/K35<=200,50,IF(I35/K35>200,ROUNDUP((50+((I35/K35-200)*0.1)),0),fault))) -> 50 | R35: =IF($K35>0, Q35*K35, 0) -> 50 | T35: B28 | W35: Cable (Duct) Tray Layout | X35: 0.3 | Y35: 0.1 | Z35: 0.3 | AA35: =ROUNDUP(AA36*0.6,0) -> 21 | AB35: 장 | AD35: C28 | AG35: 2) SPI 적용-외부
B36: A29 | E36: Rotameter | I36: 0 | J36: ea. | K36: 0 | L36: Set | M36: =IF(I36>0,산출기준_CI!$G$115,0) -> 0 | N36: =IF($K36>0, M36*K36, 0) -> 0 | O36: =IF(I36=0,0,IF(I36/K36<=200,120,IF(I36/K36>200,ROUNDUP((120+((I36/K36-200)*0.1)),0),fault))) -> 0 | P36: =IF($K36>0, O36*K36, 0) -> 0 | Q36: =IF(I36=0,0,IF(I36/K36<=200,50,IF(I36/K36>200,ROUNDUP((50+((I36/K36-200)*0.1)),0),fault))) -> 0 | R36: =IF($K36>0, Q36*K36, 0) -> 0 | T36: B29 | W36: Instrument Wiring Layout | X36: 0.3 | Y36: 0.1 | Z36: 0.3 | AA36: =ROUNDUP((SUM(I12:I20,I21,I30:I34)+SUM(I23:I25,I28:I29)*2)/30,0) -> 34 | AB36: 장 | AD36: C29 | AG36: 3) SPI 미적용
B37: A30 | E37: Level Gauge + Sight Glass | I37: 37 | J37: ea. | K37: 1 | L37: Set | M37: =IF(I37>0,산출기준_CI!$G$115,0) -> 60 | N37: =IF($K37>0, M37*K37, 0) -> 60 | O37: =IF(I37=0,0,IF(I37/K37<=200,120,IF(I37/K37>200,ROUNDUP((120+((I37/K37-200)*0.1)),0),fault))) -> 120 | P37: =IF($K37>0, O37*K37, 0) -> 120 | Q37: =IF(I37=0,0,IF(I37/K37<=200,50,IF(I37/K37>200,ROUNDUP((50+((I37/K37-200)*0.1)),0),fault))) -> 50 | R37: =IF($K37>0, Q37*K37, 0) -> 50 | T37: B30 | W37: F&G Wiring Layout | X37: 0.3 | Y37: 0.1 | Z37: 0.3 | AA37: =ROUNDUP(SUM(I40:I42)/15,0) -> 29 | AB37: 장 | AD37: C30 | AF37: ICSS IO database (IODB) | AG37: 1) SPI 적용-내부 | AH37: 2) | AJ37: =IF(AH37="1)","SPI-내부",IF(AH37="2)","SPI-외부",IF(AH37="3)","중","ERROR"))) -> SPI-외부
B38: A31 | E38: Local Gauge & Element | I38: 10 | J38: ea. | K38: 1 | L38: Set | M38: =IF(I38>0,산출기준_CI!$G$115,0) -> 60 | N38: =IF($K38>0, M38*K38, 0) -> 60 | O38: =IF(I38=0,0,IF(I38/K38<=200,120,IF(I38/K38>200,ROUNDUP((120+((I38/K38-200)*0.1)),0),fault))) -> 120 | P38: =IF($K38>0, O38*K38, 0) -> 120 | Q38: =IF(I38=0,0,IF(I38/K38<=200,50,IF(I38/K38>200,ROUNDUP((50+((I38/K38-200)*0.1)),0),fault))) -> 50 | R38: =IF($K38>0, Q38*K38, 0) -> 50 | T38: B31 | W38: Instrument Air Piping Layout | X38: 0.3 | Y38: 0.1 | Z38: 0.3 | AA38: =ROUNDUP(SUM(I21,I23,I25,I28,I29)/15,0) -> 17 | AB38: 장 | AD38: C31 | AG38: 2) SPI 적용-외부
B39: A32 | E39: Other Non-Electronic Instrument | I39: 0 | J39: ea. | K39: 0 | L39: Set | M39: =IF(I39>0,산출기준_CI!$G$115,0) -> 0 | N39: =IF($K39>0, M39*K39, 0) -> 0 | O39: =IF(I39=0,0,IF(I39/K39<=200,120,IF(I39/K39>200,ROUNDUP((120+((I39/K39-200)*0.1)),0),fault))) -> 0 | P39: =IF($K39>0, O39*K39, 0) -> 0 | Q39: =IF(I39=0,0,IF(I39<=200,50,IF(I39>200,ROUNDUP((50+((I39-200)*0.1)),0),fault))) -> 0 | R39: =IF($K39>0, Q39*K39, 0) -> 0 | T39: B32 | W39: Control Room / PIB Rack Room / Equipment & Engineering room 수량 | AA39: 8 | AB39: ea. | AD39: C32 | AG39: 3) SPI 미적용
B40: A33 | D40: F&G Devices | E40: Gas Detector & Alarm | I40: 432 | J40: ea. | K40: 1 | L40: Set | M40: =IF(I40>0,산출기준_CI!$G$115,0) -> 60 | N40: =IF($K40>0, M40*K40, 0) -> 60 | O40: =IF(I40=0,0,IF(I40/K40<=400,120,IF(I40/K40>400,ROUNDUP((120+((I40/K40-400)*0.02)),0),fault))) -> 121 | P40: =IF($K40>0, O40*K40, 0) -> 121 | Q40: =IF(I40=0,0,IF(I40/K40<=400,50,IF(I40/K40>400,ROUNDUP((50+((I40/K40-400)*0.02)),0),fault))) -> 51 | R40: =IF($K40>0, Q40*K40, 0) -> 51 | T40: B33 | W40: Control Room / PIB Equipment layout, Cable Tray Layout & Earthing Layout | X40: 0.3 | Y40: 0.1 | Z40: 0.3 | AA40: =ROUNDUP(AA39*1.5,) -> 12 | AB40: 장 | AD40: C33 | AF40: Instrument Cable Schedule | AG40: Instrument Cable Schedule | AH40: 자동생성 | AJ40: =$AJ$8 -> 상 | AK40: Project 표준 난이도 적용
...

Sheet OP1_CI
A1: C&I설계 화공 실행사업 M/H 산출서 (Rev.3) | AF1: OUTPUT1_내부-산출
A2: =CONCATENATE("[ ",산출기준_CI!A5, " ]") -> [ 일반 Ver. ]
E3: 산출 Base Data Summary
D4: G4 | E4: Total ICSS (DCS+ESD+F&G)+MMS IO 수량 | G4: =SUM(Input_CI!I8:I11) -> 6300 | H4: Actual수량만 기입 | U4: Notes
D5: G5 | E5: Total F&G 계기 수량 | G5: =SUM(Input_CI!I40:I42) -> 432 | H5: Detectors and Alarms | U5: 1 | V5: Unit M/H 난이도는 도면 별 특성이나 PJT 특성 (발주처 성향, PMC 개입여부, 승인 Level 및 절차 등) 및 Condition 등을 고려하여 결정 됨
D6: G6 | E6: Total Electronic 계기 수량 | G6: =SUM(Input_CI!I30:I34)+SUM(Input_CI!I12:I20) -> 570 | H6: F&G, CV, On-off, MOV 제외 | U6: 2 | V6: UT/OS등 Package위주이거나 모든 Package를 ICSS Control시는 PKG Cable에 관련된 도면과 SPI는 추가 M/H 반영
D7: G7 | E7: Total Non-Electronic 계기 수량 | G7: =SUM(Input_CI!I35:I39) -> 181 | H7: PSV, Rupture Disk 제외 | U7: 3 | V7: Hook-up에서 Unit별로 중복도면 출도시는 장당 0.5 M/H를 적용
D8: G8 | E8: Total Control Valve 수량 | G8: =SUM(Input_CI!I21:I22,Input_CI!I25,Input_CI!I29) -> 94 | U8: 4 | V8: SPI로 부분역무만 시행하면 전체 M/H에서 ( )에 적용된 %만큼만 적용한다 (난이도별 M/H 참조)
D9: G9 | E9: Total On-off & S/D Valve 수량 | G9: =SUM(Input_CI!I23,Input_CI!I28) -> 156 | H9: Deluge Vavle 포함 | U9: 5 | V9: SPI Calulation module등이 적용 될 시는 별도 추가 M/H 반영
D10: G10 | E10: Total MOV 수량 | G10: =Input_CI!I24 -> 7 | U10: 6 | V10: SPI Spec.에서 기계 Package UCP/LCP, Fire Alarm등 ICSS와는 관련없는 부분까지 반영 요구시 추가 M/H 반영
D11: G11 | E11: Total PSV 수량 | G11: =SUM(Input_CI!I26:I27) -> 99 | H11: Rupture Disk 포함, HEC 직 구매분만
D12: G12 | E12: Total Junction Boxes 수량 | G12: =Input_CI!I45 -> 600 | H12: HEC 직 구매분만
D13: G13 | E13: Total ST + ET Tracing 계기수량 | G13: =Input_CI!I46 -> 244
D14: G14 | E14: Total Flow & Level 계기 수량 | G14: =SUM(Input_CI!I30:I31,Input_CI!I35:I37) -> 199 | H14: 포함 수량 in G6 & G7 (for 3D Library)
A15: =Input_CI!B5 -> PROJECT: Promigas CPF Project | Q15: FOR GEC | R15: FOR GEC | S15: FOR GEC | T15: FOR GEC | AD15: =Input_CI!AK5 -> 46255 | AF15: Rev.3
A16: MAN-HOUR 산출 TABLE
A17: 대분류 (G, E, P, C) | B17: 중분류 (Activity) | C17: CATEGORY | D17: MH 산출 항목 | F17: 단위 | G17: 수량 | H17: 난이도 | I17: 내부 M/H (HEC M/H) | O17: GEC M/H | Q17: GEC M/H 세부내역_내부 (내부 M/H 대체 부분) | S17: GEC M/H 세부내역_외부 (외부 M/H 대체 부분) | U17: 외부 M/H | AA17: Total M/H | AD17: Remarks
I18: Case1 | K18: Case2 | M18: Case3 | O18: Case2 & Case3 | Q18: Case2 & Case3 | S18: Case2 & Case3 | U18: Case1 | W18: Case2 | Y18: Case3 | AA18: Case1 | AB18: Case2 | AC18: Case3
I19: 외주-단종 Case | K19: 'GEC & 외주-단종' Case | M19: 'GEC & 외주-종합' Case | O19: 'GEC & 외주-단종' Case / 'GEC & 외주-종합' Case | Q19: 'GEC & 외주-단종' Case / 'GEC & 외주-종합' Case | S19: 'GEC & 외주-단종' Case / 'GEC & 외주-종합' Case | U19: 외주-단종 Case (외주-단종) | W19: 'GEC & 외주-단종' Case (외주-단종) | Y19: 'GEC & 외주-종합' Case (외주-종합) | AA19: 외주-단종 Case | AB19: GEC & 외주-단종 Case | AC19: GEC & 외주-종합 Case
I20: Unit M/H | J20: M/H | K20: Unit M/H | L20: M/H | M20: Unit M/H | N20: M/H | O20: Unit M/H | P20: M/H | Q20: Unit M/H | R20: M/H | S20: Unit M/H | T20: M/H | U20: Unit M/H | V20: M/H | W20: Unit M/H | X20: M/H | Y20: Unit M/H | Z20: M/H | AA20: Total M/H | AB20: Total M/H | AC20: Total M/H
A21: G (General) | B21: 마일스톤 연계 미팅 | C21: G1 | D21: 1) | E21: Meeting & Coordination | F21: Lot | G21: 1 | H21: =Input_CI!$AJ$8 -> 상 | I21: =IF(H21="상",산출기준_CI!F14,IF(H21="중",산출기준_CI!G14,IF(H21="하",산출기준_CI!H14,fault))) -> 120 | J21: =ROUND((G21*I21),0) -> 120 | K21: =$I21*(1-Input_CI!$F47) -> 84 | L21: =ROUND(K21*G21,0) -> 84 | M21: =$I21*(1-Input_CI!$F47-Input_CI!$G47) -> 72 | N21: =ROUND(M21*G21,0) -> 72 | O21: =Q21+S21 -> 51.428571 | P21: =R21+T21 -> 51 | Q21: =$I21*(Input_CI!$F47)/Input_CI!$AH$75 -> 51.428571 | R21: =ROUND(Q21*G21,0) -> 51 | Y21: =$U21*(1-Input_CI!$H$47)+I21*Input_CI!$G$47/Input_CI!$AH$76 -> 17.142857 | Z21: =ROUND(Y21*G21,0) -> 17 | AA21: =SUM(J21,V21) -> 120 | AB21: =L21+P21+X21 -> 135 | AC21: =N21+P21+Z21 -> 140
D22: 2) | E22: Design Review (30%, 60%, 90%) | F22: Lot | G22: 1 | H22: =Input_CI!$AJ$8 -> 상 | I22: =IF(H22="상",산출기준_CI!F15,IF(H22="중",산출기준_CI!G15,IF(H22="하",산출기준_CI!H15,fault))) -> 180 | J22: =ROUND((G22*I22),0) -> 180 | K22: =$I22*(1-Input_CI!$F48) -> 126 | L22: =ROUND(K22*G22,0) -> 126 | M22: =$I22*(1-Input_CI!$F48-Input_CI!$G48) -> 108 | N22: =ROUND(M22*G22,0) -> 108 | O22: =Q22+S22 -> 77.142857 | P22: =R22+T22 -> 77 | Q22: =$I22*(Input_CI!$F48)/Input_CI!$AH$75 -> 77.142857 | R22: =ROUND(Q22*G22,0) -> 77 | Y22: =$U22*(1-Input_CI!$H$48)+I22*Input_CI!$G$48/Input_CI!$AH$76 -> 25.714286 | Z22: =ROUND(Y22*G22,0) -> 26 | AA22: =SUM(J22,V22) -> 180 | AB22: =L22+P22+X22 -> 203 | AC22: =N22+P22+Z22 -> 211
D23: 3) | E23: Workshop (ITB, Package, VELL) | F23: Lot | G23: 1 | H23: =Input_CI!$AJ$8 -> 상 | I23: =IF(H23="상",산출기준_CI!F16,IF(H23="중",산출기준_CI!G16,IF(H23="하",산출기준_CI!H16,fault))) -> 80 | J23: =ROUND((G23*I23),0) -> 80 | K23: =$I23*(1-Input_CI!$F49) -> 80 | L23: =ROUND(K23*G23,0) -> 80 | M23: =$I23*(1-Input_CI!$F49-Input_CI!$G49) -> 80 | N23: =ROUND(M23*G23,0) -> 80 | O23: =Q23+S23 -> 0 | P23: =R23+T23 -> 0 | Q23: =$I23*(Input_CI!$F49)/Input_CI!$AH$75 -> 0 | R23: =ROUND(Q23*G23,0) -> 0 | Y23: =$U23*(1-Input_CI!$H$48)+I23*Input_CI!$G$48/Input_CI!$AH$76 -> 11.428571 | Z23: =ROUND(Y23*G23,0) -> 11 | AA23: =SUM(J23,V23) -> 80 | AB23: =L23+P23+X23 -> 80 | AC23: =N23+P23+Z23 -> 91
B24: ITB Review / FEED Verifi. / CER | C24: G2 | D24: 1) | E24: ITB Review & Interface work. | F24: Lot | G24: 1 | H24: =Input_CI!$AJ$8 -> 상 | I24: =IF(H24="상",산출기준_CI!F19,IF(H24="중",산출기준_CI!G19,IF(H24="하",산출기준_CI!H19,fault))) -> 340 | J24: =ROUND((G24*I24),0) -> 340 | K24: =$I24*(1-Input_CI!$F50) -> 238 | L24: =ROUND(K24*G24,0) -> 238 | M24: =$I24*(1-Input_CI!$F50-Input_CI!$G50) -> 204 | N24: =ROUND(M24*G24,0) -> 204 | O24: =Q24+S24 -> 145.71429 | P24: =R24+T24 -> 146 | Q24: =$I24*(Input_CI!$F50)/Input_CI!$AH$75 -> 145.71429 | R24: =ROUND(Q24*G24,0) -> 146 | Y24: =$U24*(1-Input_CI!$H$50)+I24*Input_CI!$G$50/Input_CI!$AH$76 -> 48.571429 | Z24: =ROUND(Y24*G24,0) -> 49 | AA24: =SUM(J24,V24) -> 340 | AB24: =L24+P24+X24 -> 384 | AC24: =N24+P24+Z24 -> 399
D25: 2) | E25: 발주처 협의 (Technical Clarification) | F25: 명 | G25: =Input_CI!I51 -> 5 | H25: =Input_CI!$AJ$8 -> 상 | I25: =IF(H25="상",산출기준_CI!F20,IF(H25="중",산출기준_CI!G20,IF(H25="하",산출기준_CI!H20,fault))) -> 80 | J25: =ROUND((G25*I25),0) -> 400 | K25: =$I25*(1-Input_CI!$F51) -> 56 | L25: =ROUND(K25*G25,0) -> 280 | M25: =$I25*(1-Input_CI!$F51-Input_CI!$G51) -> 48 | N25: =ROUND(M25*G25,0) -> 240 | O25: =Q25+S25 -> 34.285714 | P25: =R25+T25 -> 171 | Q25: =$I25*(Input_CI!$F51)/Input_CI!$AH$75 -> 34.285714 | R25: =ROUND(Q25*G25,0) -> 171 | Y25: =$U25*(1-Input_CI!$H$51)+I25*Input_CI!$G$51/Input_CI!$AH$76 -> 11.428571 | Z25: =ROUND(Y25*G25,0) -> 57 | AA25: =SUM(J25,V25) -> 400 | AB25: =L25+P25+X25 -> 451 | AC25: =N25+P25+Z25 -> 468
D26: 3) | E26: Feed Verification | F26: 명 | G26: =Input_CI!I52 -> 5 | H26: =Input_CI!$AJ$8 -> 상 | I26: =IF(H26="상",산출기준_CI!F21,IF(H26="중",산출기준_CI!G21,IF(H26="하",산출기준_CI!H21,fault))) -> 80 | J26: =ROUND((G26*I26),0) -> 400 | K26: =$I26*(1-Input_CI!$F52) -> 56 | L26: =ROUND(K26*G26,0) -> 280 | M26: =$I26*(1-Input_CI!$F52-Input_CI!$G52) -> 48 | N26: =ROUND(M26*G26,0) -> 240 | O26: =Q26+S26 -> 34.285714 | P26: =R26+T26 -> 171 | Q26: =$I26*(Input_CI!$F52)/Input_CI!$AH$75 -> 34.285714 | R26: =ROUND(Q26*G26,0) -> 171 | Y26: =$U26*(1-Input_CI!$H$52)+I26*Input_CI!$G$52/Input_CI!$AH$76 -> 11.428571 | Z26: =ROUND(Y26*G26,0) -> 57 | AA26: =SUM(J26,V26) -> 400 | AB26: =L26+P26+X26 -> 451 | AC26: =N26+P26+Z26 -> 468
D27: 4) | E27: Early Work | F27: 명 | G27: =Input_CI!I53 -> 0 | H27: =Input_CI!$AJ$8 -> 상 | I27: =IF(H27="상",산출기준_CI!F22,IF(H27="중",산출기준_CI!G22,IF(H27="하",산출기준_CI!H22,fault))) -> 400 | J27: =ROUND((G27*I27),0) -> 0 | K27: =$I27*(1-Input_CI!$F53) -> 280 | L27: =ROUND(K27*G27,0) -> 0 | M27: =$I27*(1-Input_CI!$F53-Input_CI!$G53) -> 240 | N27: =ROUND(M27*G27,0) -> 0 | O27: =Q27+S27 -> 171.42857 | P27: =R27+T27 -> 0 | Q27: =$I27*(Input_CI!$F53)/Input_CI!$AH$75 -> 171.42857 | R27: =ROUND(Q27*G27,0) -> 0 | Y27: =$U27*(1-Input_CI!$H$53)+I27*Input_CI!$G$53/Input_CI!$AH$76 -> 57.142857 | Z27: =ROUND(Y27*G27,0) -> 0 | AA27: =SUM(J27,V27) -> 0 | AB27: =L27+P27+X27 -> 0 | AC27: =N27+P27+Z27 -> 0
D28: 5) | E28: Cold Eye Review (Project Team) | F28: 명 | G28: =Input_CI!I54 -> 5 | H28: =Input_CI!$AJ$8 -> 상 | I28: =IF(H28="상",산출기준_CI!F23,IF(H28="중",산출기준_CI!G23,IF(H28="하",산출기준_CI!H23,fault))) -> 16 | J28: =ROUND((G28*I28),0) -> 80 | K28: =$I28*(1-Input_CI!$F54) -> 11.2 | L28: =ROUND(K28*G28,0) -> 56 | M28: =$I28*(1-Input_CI!$F54-Input_CI!$G54) -> 9.6 | N28: =ROUND(M28*G28,0) -> 48 | O28: =Q28+S28 -> 6.8571429 | P28: =R28+T28 -> 34 | Q28: =$I28*(Input_CI!$F54)/Input_CI!$AH$75 -> 6.8571429 | R28: =ROUND(Q28*G28,0) -> 34 | Y28: =$U28*(1-Input_CI!$H$53)+I28*Input_CI!$G$53/Input_CI!$AH$76 -> 2.2857143 | Z28: =ROUND(Y28*G28,0) -> 11 | AA28: =SUM(J28,V28) -> 80 | AB28: =L28+P28+X28 -> 90 | AC28: =N28+P28+Z28 -> 93
B29: Subtotal (G) | J29: =SUM(J21:J28) -> 1600 | L29: =SUM(L21:L28) -> 1144 | N29: =SUM(N21:N28) -> 992 | P29: =SUM(P21:P28) -> 650 | R29: =SUM(R21:R28) -> 650 | T29: =SUM(T21:T28) -> 0 | V29: =SUM(V21:V28) -> 0 | X29: =SUM(X21:X28) -> 0 | Z29: =SUM(Z21:Z28) -> 228 | AA29: =SUM(J29,V29) -> 1600 | AB29: =L29+P29+X29 -> 1794 | AC29: =N29+P29+Z29 -> 1870
A30: E (설계관련) | B30: Design Basis / Specification | C30: E1 | D30: 1) | E30: Technical Specification
E31: - Control System | F31: Set | G31: 0 | H31: =Input_CI!$AJ$21 -> 중 | I31: =IF(H31="상",산출기준_CI!F28,IF(H31="중",산출기준_CI!G28,IF(H31="하",산출기준_CI!H28,fault))) -> 120 | J31: =ROUND((G31*I31),0) -> 0 | K31: =$I31*(1-Input_CI!$X8) -> 84 | L31: =ROUND(K31*G31,0) -> 0 | M31: =$I31*(1-Input_CI!$X8-Input_CI!$Y8) -> 72 | N31: =ROUND(M31*G31,0) -> 0 | O31: =Q31+S31 -> 51.428571 | P31: =R31+T31 -> 0 | Q31: =$I31*(Input_CI!$X8)/Input_CI!$AH$75 -> 51.428571 | R31: =ROUND(Q31*G31,0) -> 0 | Y31: =$U31*(1-Input_CI!$Z8)+I31*Input_CI!$Y8/Input_CI!$AH$76 -> 17.142857 | Z31: =ROUND(Y31*G31,0) -> 0 | AA31: =SUM(J31,V31) -> 0 | AB31: =L31+P31+X31 -> 0 | AC31: =N31+P31+Z31 -> 0
E32: - Packaged Instrument | F32: Set | G32: 0 | H32: =Input_CI!$AJ$24 -> 중 | I32: =IF(H32="상",산출기준_CI!F29,IF(H32="중",산출기준_CI!G29,IF(H32="하",산출기준_CI!H29,fault))) -> 70 | J32: =ROUND((G32*I32),0) -> 0 | K32: =$I32*(1-Input_CI!$X9) -> 49 | L32: =ROUND(K32*G32,0) -> 0 | M32: =$I32*(1-Input_CI!$X9-Input_CI!$Y9) -> 42 | N32: =ROUND(M32*G32,0) -> 0 | O32: =Q32+S32 -> 30 | P32: =R32+T32 -> 0 | Q32: =$I32*(Input_CI!$X9)/Input_CI!$AH$75 -> 30 | R32: =ROUND(Q32*G32,0) -> 0 | Y32: =$U32*(1-Input_CI!$Z9)+I32*Input_CI!$Y9/Input_CI!$AH$76 -> 10 | Z32: =ROUND(Y32*G32,0) -> 0 | AA32: =SUM(J32,V32) -> 0 | AB32: =L32+P32+X32 -> 0 | AC32: =N32+P32+Z32 -> 0
E33: - Field Instrument | F33: Set | G33: 0 | H33: =Input_CI!$AJ$27 -> 중 | I33: =IF(H33="상",산출기준_CI!F30,IF(H33="중",산출기준_CI!G30,IF(H33="하",산출기준_CI!H30,fault))) -> 35 | J33: =ROUND((G33*I33),0) -> 0 | K33: =$I33*(1-Input_CI!$X10) -> 24.5 | L33: =ROUND(K33*G33,0) -> 0 | M33: =$I33*(1-Input_CI!$X10-Input_CI!$Y10) -> 21 | N33: =ROUND(M33*G33,0) -> 0 | O33: =Q33+S33 -> 15 | P33: =R33+T33 -> 0 | Q33: =$I33*(Input_CI!$X10)/Input_CI!$AH$75 -> 15 | R33: =ROUND(Q33*G33,0) -> 0 | Y33: =$U33*(1-Input_CI!$Z10)+I33*Input_CI!$Y10/Input_CI!$AH$76 -> 5 | Z33: =ROUND(Y33*G33,0) -> 0 | AA33: =SUM(J33,V33) -> 0 | AB33: =L33+P33+X33 -> 0 | AC33: =N33+P33+Z33 -> 0
E34: - Others | F34: Set | G34: 0 | H34: =Input_CI!$AJ$30 -> 중 | I34: =IF(H34="상",산출기준_CI!F31,IF(H34="중",산출기준_CI!G31,IF(H34="하",산출기준_CI!H31,fault))) -> 35 | J34: =ROUND((G34*I34),0) -> 0 | K34: =$I34*(1-Input_CI!$X11) -> 24.5 | L34: =ROUND(K34*G34,0) -> 0 | M34: =$I34*(1-Input_CI!$X11-Input_CI!$Y11) -> 21 | N34: =ROUND(M34*G34,0) -> 0 | O34: =Q34+S34 -> 15 | P34: =R34+T34 -> 0 | Q34: =$I34*(Input_CI!$X11)/Input_CI!$AH$75 -> 15 | R34: =ROUND(Q34*G34,0) -> 0 | Y34: =$U34*(1-Input_CI!$Z11)+I34*Input_CI!$Y11/Input_CI!$AH$76 -> 5 | Z34: =ROUND(Y34*G34,0) -> 0 | AA34: =SUM(J34,V34) -> 0 | AB34: =L34+P34+X34 -> 0 | AC34: =N34+P34+Z34 -> 0
D35: 2) | E35: Design Basis 작성 | F35: Lot | G35: 1 | H35: =Input_CI!$AJ$33 -> 상 | I35: =IF(H35="상",산출기준_CI!F32,IF(H35="중",산출기준_CI!G32,IF(H35="하",산출기준_CI!H32,fault))) -> 340 | J35: =ROUND((G35*I35),0) -> 340 | K35: =$I35*(1-Input_CI!$X12) -> 238 | L35: =ROUND(K35*G35,0) -> 238 | M35: =$I35*(1-Input_CI!$X12-Input_CI!$Y12) -> 204 | N35: =ROUND(M35*G35,0) -> 204 | O35: =Q35+S35 -> 145.71429 | P35: =R35+T35 -> 146 | Q35: =$I35*(Input_CI!$X12)/Input_CI!$AH$75 -> 145.71429 | R35: =ROUND(Q35*G35,0) -> 146 | Y35: =$U35*(1-Input_CI!$Z12)+I35*Input_CI!$Y12/Input_CI!$AH$76 -> 48.571429 | Z35: =ROUND(Y35*G35,0) -> 49 | AA35: =SUM(J35,V35) -> 340 | AB35: =L35+P35+X35 -> 384 | AC35: =N35+P35+Z35 -> 399
B36: Summary / List / Table | C36: E2 | D36: 1) | E36: Instrument Index | F36: Ea | G36: =ROUNDUP((G5+G6+G7+G8+G9+G10+G11),0) -> 1539 | H36: =Input_CI!$AJ$34 -> SPI-외부 | I36: =IF(H36="SPI-내부",산출기준_CI!E35,산출기준_CI!G35) -> 0.5 | J36: =ROUND((G36*I36),0) -> 770 | K36: =$I36*(1-Input_CI!$X13) -> 0.35 | L36: =ROUND(K36*G36,0) -> 539 | M36: =$I36*(1-Input_CI!$X13-Input_CI!$Y13) -> 0.3 | N36: =ROUND(M36*G36,0) -> 462 | O36: =Q36+S36 -> 0.27428571 | P36: =R36+T36 -> 422 | Q36: =$I36*(Input_CI!$X13)/Input_CI!$AH$75 -> 0.21428571 | R36: =ROUND(Q36*G36,0) -> 330 | S36: =U36*Input_CI!$Z13 -> 0.06 | T36: =ROUND(S36*G36,0) -> 92 | U36: =IF(H36="SPI-외부",산출기준_CI!I35,산출기준_CI!K35) -> 0.2 | V36: =ROUND((G36*U36),0) -> 308 | W36: =$U36*(1-Input_CI!$Z13) -> 0.14 | X36: =ROUND(W36*G36,0) -> 215 | Y36: =$U36*(1-Input_CI!$Z13)+I36*Input_CI!$Y13/Input_CI!$AH$76 -> 0.21142857 | Z36: =ROUND(Y36*G36,0) -> 325 | AA36: =SUM(J36,V36) -> 1078 | AB36: =L36+P36+X36 -> 1176 | AC36: =N36+P36+Z36 -> 1209 | AD36: *SPI
D37: 2) | E37: ICSS IO database (IODB) | F37: Point | G37: =ROUNDUP((G4),0) -> 6300 | H37: =Input_CI!$AJ$37 -> SPI-외부 | I37: =IF(H37="SPI-내부",산출기준_CI!E36,산출기준_CI!G36) -> 0.3 | J37: =ROUND((G37*I37),0) -> 1890 | K37: =$I37*(1-Input_CI!$X14) -> 0.21 | L37: =ROUND(K37*G37,0) -> 1323 | M37: =$I37*(1-Input_CI!$X14-Input_CI!$Y14) -> 0.18 | N37: =ROUND(M37*G37,0) -> 1134 | O37: =Q37+S37 -> 0.21857143 | P37: =R37+T37 -> 1377 | Q37: =$I37*(Input_CI!$X14)/Input_CI!$AH$75 -> 0.12857143 | R37: =ROUND(Q37*G37,0) -> 810 | S37: =U37*Input_CI!$Z14 -> 0.09 | T37: =ROUND(S37*G37,0) -> 567 | U37: =IF(H37="SPI-외부",산출기준_CI!I36,산출기준_CI!K36) -> 0.3 | V37: =ROUND((G37*U37),0) -> 1890 | W37: =$U37*(1-Input_CI!$Z14) -> 0.21 | X37: =ROUND(W37*G37,0) -> 1323 | Y37: =$U37*(1-Input_CI!$Z14)+I37*Input_CI!$Y14/Input_CI!$AH$76 -> 0.25285714 | Z37: =ROUND(Y37*G37,0) -> 1593 | AA37: =SUM(J37,V37) -> 3780 | AB37: =L37+P37+X37 -> 4023 | AC37: =N37+P37+Z37 -> 4104 | AD37: *SPI
D38: 3) | E38: Instrument Cable Schedule | F38: A4 | G38: 0 | H38: =Input_CI!$AJ$40 -> 상 | I38: =IF(H38="상",산출기준_CI!F37,IF(H38="중",산출기준_CI!G37,IF(H38="하",산출기준_CI!H37,fault))) -> 0.3 | J38: =ROUND((G38*I38),0) -> 0 | K38: =$I38*(1-Input_CI!$X15) -> 0.21 | L38: =ROUND(K38*G38,0) -> 0 | M38: =$I38*(1-Input_CI!$X15-Input_CI!$Y15) -> 0.18 | N38: =ROUND(M38*G38,0) -> 0 | O38: =Q38+S38 -> 1.3285714 | P38: =R38+T38 -> 0 | Q38: =$I38*(Input_CI!$X15)/Input_CI!$AH$75 -> 0.12857143 | R38: =ROUND(Q38*G38,0) -> 0 | S38: =U38*Input_CI!$Z15 -> 1.2 | T38: =ROUND(S38*G38,0) -> 0 | U38: =IF(H38="상",산출기준_CI!J37,IF(H38="중",산출기준_CI!K37,IF(H38="하",산출기준_CI!L37,fault))) -> 4 | V38: =ROUND((G38*U38),0) -> 0 | W38: =$U38*(1-Input_CI!$Z15) -> 2.8 | X38: =ROUND(W38*G38,0) -> 0 | Y38: =$U38*(1-Input_CI!$Z15)+I38*Input_CI!$Y15/Input_CI!$AH$76 -> 2.8428571 | Z38: =ROUND(Y38*G38,0) -> 0 | AA38: =SUM(J38,V38) -> 0 | AB38: =L38+P38+X38 -> 0 | AC38: =N38+P38+Z38 -> 0
D39: 4) | E39: UPS / Normal Power Load List | F39: Lot | G39: 1 | H39: N/A | I39: =산출기준_CI!G38 -> 50 | J39: =ROUND((G39*I39),0) -> 50 | K39: =$I39*(1-Input_CI!$X16) -> 35 | L39: =ROUND(K39*G39,0) -> 35 | M39: =$I39*(1-Input_CI!$X16-Input_CI!$Y16) -> 30 | N39: =ROUND(M39*G39,0) -> 30 | O39: =Q39+S39 -> 21.428571 | P39: =R39+T39 -> 21 | Q39: =$I39*(Input_CI!$X16)/Input_CI!$AH$75 -> 21.428571 | R39: =ROUND(Q39*G39,0) -> 21 | Y39: =$U39*(1-Input_CI!$Z16)+I39*Input_CI!$Y16/Input_CI!$AH$76 -> 7.1428571 | Z39: =ROUND(Y39*G39,0) -> 7 | AA39: =SUM(J39,V39) -> 50 | AB39: =L39+P39+X39 -> 56 | AC39: =N39+P39+Z39 -> 58
D40: 5) | E40: Heat Dissipation List | F40: Lot | G40: 1 | H40: N/A | I40: =산출기준_CI!G39 -> 50 | J40: =ROUND((G40*I40),0) -> 50 | K40: =$I40*(1-Input_CI!$X17) -> 35 | L40: =ROUND(K40*G40,0) -> 35 | M40: =$I40*(1-Input_CI!$X17-Input_CI!$Y17) -> 30 | N40: =ROUND(M40*G40,0) -> 30 | O40: =Q40+S40 -> 21.428571 | P40: =R40+T40 -> 21 | Q40: =$I40*(Input_CI!$X17)/Input_CI!$AH$75 -> 21.428571 | R40: =ROUND(Q40*G40,0) -> 21 | Y40: =$U40*(1-Input_CI!$Z17)+I40*Input_CI!$Y17/Input_CI!$AH$76 -> 7.1428571 | Z40: =ROUND(Y40*G40,0) -> 7 | AA40: =SUM(J40,V40) -> 50 | AB40: =L40+P40+X40 -> 56 | AC40: =N40+P40+Z40 -> 58
...

Sheet OP2-1_CI
B1: 설계소요 M/H 내역 (C&I) - 실행 | N1: OUTPUT2-1_외부-보고: 외주-단종
B2: =CONCATENATE("외주-단종 Case [",산출기준_CI!A5,"]") -> 외주-단종 Case [일반 Ver.] | N2: Case1
B3: =OP1_CI!A15 -> PROJECT: Promigas CPF Project | L3: =Input_CI!AK5 -> 46255 | N3: REV.3
B4: 구 분 | C4: Activity | D4: Size | E4: 내 부 | H4: 외 주 - 단 종 | K4: Total M/H | L4: 비 고
B5: No. | E5: Unit M/H | F5: Quantity | G5: M/H | H5: Unit M/H | I5: Quantity | J5: M/H
B7: G | C7: GENERAL
B8: 1 | C8: 마일스톤 연계 미팅
B9: 1.1 | C9: Meeting & Coordination | D9: Lot | E9: =OP1_CI!I21 -> 120 | F9: =OP1_CI!$G21 -> 1 | G9: =OP1_CI!J21 -> 120 | J9: =OP1_CI!V21 -> 0 | K9: =G9+J9 -> 120
B10: 1.2 | C10: Design Review (30%, 60%, 90%) | D10: Lot | E10: =OP1_CI!I22 -> 180 | F10: =OP1_CI!$G22 -> 1 | G10: =OP1_CI!J22 -> 180 | J10: =OP1_CI!V22 -> 0 | K10: =G10+J10 -> 180
B11: 1.3 | C11: Workshop (ITB, Package, VELL) | D11: Lot | E11: =OP1_CI!I23 -> 80 | F11: =OP1_CI!$G23 -> 1 | G11: =OP1_CI!J23 -> 80 | J11: =OP1_CI!V23 -> 0 | K11: =G11+J11 -> 80
B13: 2 | C13: ITB Review / FEED Verification
B14: 2.1 | C14: ITB Review & Interface work. | D14: Lot | E14: =OP1_CI!I24 -> 340 | F14: =OP1_CI!$G24 -> 1 | G14: =OP1_CI!J24 -> 340 | H14: 0 | I14: 0 | J14: =OP1_CI!V24 -> 0 | K14: =G14+J14 -> 340
B15: 2.2 | C15: 발주처 협의 (Technical Clarification) | D15: 명 | E15: =OP1_CI!I25 -> 80 | F15: =OP1_CI!$G25 -> 5 | G15: =OP1_CI!J25 -> 400 | J15: =OP1_CI!V25 -> 0 | K15: =G15+J15 -> 400
B16: 2.3 | C16: Feed Verification | D16: 명 | E16: =OP1_CI!I26 -> 80 | F16: =OP1_CI!$G26 -> 5 | G16: =OP1_CI!J26 -> 400 | J16: =OP1_CI!V26 -> 0 | K16: =G16+J16 -> 400
B17: 2.4 | C17: Early Work | D17: 명 | E17: =OP1_CI!I27 -> 400 | F17: =OP1_CI!$G27 -> 0 | G17: =OP1_CI!J27 -> 0 | J17: =OP1_CI!V27 -> 0 | K17: =G17+J17 -> 0
B18: 2.5 | C18: Cold Eye Review | D18: 명 | E18: =OP1_CI!I28 -> 16 | F18: =OP1_CI!$G28 -> 5 | G18: =OP1_CI!J28 -> 80 | J18: =OP1_CI!V28 -> 0 | K18: =G18+J18 -> 80
B20: SUB-TOTAL (G. GENERAL M/H) | G20: =SUM(G7:G19) -> 1600 | J20: =SUM(J7:J19) -> 0 | K20: =SUM(K7:K19) -> 1600
B22: E | C22: 설계 관련
B23: 1 | C23: Design Basis / Specification
B24: 1.1 | C24: Technical Specification | H24: 0 | I24: 0
C25: - Control System | D25: Set | E25: =OP1_CI!I31 -> 120 | F25: =OP1_CI!$G31 -> 0 | G25: =OP1_CI!J31 -> 0 | H25: 0 | I25: 0 | K25: =G25+J25 -> 0
C26: - Packaged Instrument | D26: Set | E26: =OP1_CI!I32 -> 70 | F26: =OP1_CI!$G32 -> 0 | G26: =OP1_CI!J32 -> 0 | H26: 0 | I26: 0 | K26: =G26+J26 -> 0
C27: - Field Instrument | D27: Set | E27: =OP1_CI!I33 -> 35 | F27: =OP1_CI!$G33 -> 0 | G27: =OP1_CI!J33 -> 0 | H27: 0 | I27: 0 | K27: =G27+J27 -> 0
C28: - Others | D28: Set | E28: =OP1_CI!I34 -> 35 | F28: =OP1_CI!$G34 -> 0 | G28: =OP1_CI!J34 -> 0 | H28: 0 | I28: 0 | K28: =G28+J28 -> 0
B29: 1.2 | C29: Design Basis 작성 | D29: Lot | E29: =OP1_CI!I35 -> 340 | F29: =OP1_CI!$G35 -> 1 | G29: =OP1_CI!J35 -> 340 | J29: =OP1_CI!V35 -> 0 | K29: =G29+J29 -> 340
B31: 2 | C31: Summary / List / Table
B32: 2.1 | C32: Instrument Index | D32: Ea | E32: =OP1_CI!I36 -> 0.5 | F32: =OP1_CI!$G36 -> 1539 | G32: =OP1_CI!J36 -> 770 | H32: =OP1_CI!U36 -> 0.2 | I32: =F32 -> 1539 | J32: =OP1_CI!V36 -> 308 | K32: =G32+J32 -> 1078
B33: 2.2 | C33: ICSS IO database (IODB) | D33: Point | E33: =OP1_CI!I37 -> 0.3 | F33: =OP1_CI!$G37 -> 6300 | G33: =OP1_CI!J37 -> 1890 | H33: =OP1_CI!U37 -> 0.3 | I33: =F33 -> 6300 | J33: =OP1_CI!V37 -> 1890 | K33: =G33+J33 -> 3780
B34: 2.3 | C34: Instrument Cable Schedule | D34: A4 | E34: =OP1_CI!I38 -> 0.3 | F34: =OP1_CI!$G38 -> 0 | G34: =OP1_CI!J38 -> 0 | H34: =OP1_CI!U38 -> 4 | I34: =F34 -> 0 | J34: =OP1_CI!V38 -> 0 | K34: =G34+J34 -> 0
B35: 2.4 | C35: UPS / Normal Power Load List | D35: Lot | E35: =OP1_CI!I39 -> 50 | F35: =OP1_CI!$G39 -> 1 | G35: =OP1_CI!J39 -> 50 | J35: =OP1_CI!V39 -> 0 | K35: =G35+J35 -> 50
B36: 2.5 | C36: Heat Dissipation List | D36: Lot | E36: =OP1_CI!I40 -> 50 | F36: =OP1_CI!$G40 -> 1 | G36: =OP1_CI!J40 -> 50 | J36: =OP1_CI!V40 -> 0 | K36: =G36+J36 -> 50
B37: 2.6 | C37: Electrical / Steam Tracing List | D37: Lot | E37: =OP1_CI!I41 -> 100 | F37: =OP1_CI!$G41 -> 1 | G37: =OP1_CI!J41 -> 100 | H37: =OP1_CI!U41 -> 100 | I37: =F37 -> 1 | J37: =OP1_CI!V41 -> 100 | K37: =G37+J37 -> 200
B38: 2.7 | C38: 3D Library Data | D38: Lot | E38: =OP1_CI!I42 -> 0.1 | F38: =OP1_CI!$G42 -> 555 | G38: =OP1_CI!J42 -> 56 | K38: =G38+J38 -> 56
B39: 2.8 | C39: Cable Tray/Duct Loading Data | D39: Lot | E39: =OP1_CI!I43 -> 50 | F39: =OP1_CI!$G43 -> 1 | G39: =OP1_CI!J43 -> 50 | H39: =OP1_CI!U43 -> 50 | I39: =F39 -> 1 | J39: =OP1_CI!V43 -> 50 | K39: =G39+J39 -> 100
B40: 2.9 | C40: 타부서 Information_Others | D40: Lot | E40: =OP1_CI!I44 -> 50 | F40: =OP1_CI!$G44 -> 1 | G40: =OP1_CI!J44 -> 50 | H40: =OP1_CI!U44 -> 50 | I40: =F40 -> 1 | J40: =OP1_CI!V44 -> 50 | K40: =G40+J40 -> 100
B42: 3 | C42: Calculation
B43: 3.1 | C43: Weak Frequency Calculation for Thermowell | D43: Ea | E43: =OP1_CI!I45 -> 0.5 | F43: =OP1_CI!$G45 -> 0 | G43: =OP1_CI!J45 -> 0 | H43: 0 | I43: 0 | J43: =OP1_CI!V45 -> 0 | K43: =G43+J43 -> 0
B44: 3.2 | C44: Cv (Valve Coefficient) Calculation for Sizing | D44: Ea | E44: =OP1_CI!I46 -> 0.5 | F44: =OP1_CI!$G46 -> 0 | G44: =OP1_CI!J46 -> 0 | H44: 0 | I44: 0 | J44: =OP1_CI!V46 -> 0 | K44: =G44+J44 -> 0
B45: 3.3 | C45: PSV Orificice Calculation for Sizing | D45: Ea | E45: =OP1_CI!I47 -> 0.5 | F45: =OP1_CI!$G47 -> 0 | G45: =OP1_CI!J47 -> 0 | H45: 0 | I45: 0 | J45: =OP1_CI!V47 -> 0 | K45: =G45+J45 -> 0
B46: 3.4 | C46: Flow Element Calculation | D46: Ea | E46: =OP1_CI!I48 -> 0.5 | F46: =OP1_CI!$G48 -> 0 | G46: =OP1_CI!J48 -> 0 | H46: 0 | I46: 0 | J46: =OP1_CI!V48 -> 0 | K46: =G46+J46 -> 0
...

Sheet OP2-2_CI
B1: 설계소요 M/H 내역 (C&I) - 실행 | Q1: OUTPUT2-2_외부-보고: GEC + 외주-단종
B2: =CONCATENATE("GEC & 외주-단종 Case [",산출기준_CI!A5,"]") -> GEC & 외주-단종 Case [일반 Ver.] | Q2: Case2
B3: =OP1_CI!A15 -> PROJECT: Promigas CPF Project | O3: =Input_CI!AK5 -> 46255 | Q3: REV.3
B4: 구 분 | C4: Activity | D4: Size | E4: 내 부 | H4: G E C | K4: 외 주 - 단 종 | N4: Total M/H | O4: 비 고
B5: No. | E5: Unit M/H | F5: Quantity | G5: M/H | H5: Unit M/H | I5: Quantity | J5: M/H | K5: Unit M/H | L5: Quantity | M5: M/H
B7: G | C7: GENERAL
B8: 1 | C8: 마일스톤 연계 미팅
B9: 1.1 | C9: Meeting & Coordination | D9: Lot | E9: =OP1_CI!K21 -> 84 | F9: =OP1_CI!G21 -> 1 | G9: =OP1_CI!L21 -> 84 | H9: =OP1_CI!O21 -> 51.428571 | I9: =F9 -> 1 | J9: =OP1_CI!P21 -> 51 | N9: =G9+J9+M9 -> 135
B10: 1.2 | C10: Design Review (30%, 60%, 90%) | D10: Lot | E10: =OP1_CI!K22 -> 126 | F10: =OP1_CI!G22 -> 1 | G10: =OP1_CI!L22 -> 126 | H10: =OP1_CI!O22 -> 77.142857 | I10: =F10 -> 1 | J10: =OP1_CI!P22 -> 77 | N10: =G10+J10+M10 -> 203
B11: 1.3 | C11: Workshop (ITB, Package, VELL) | D11: Lot | E11: =OP1_CI!K23 -> 80 | F11: =OP1_CI!G23 -> 1 | G11: =OP1_CI!L23 -> 80 | H11: =OP1_CI!O23 -> 0 | I11: =F11 -> 1 | J11: =OP1_CI!P23 -> 0 | N11: =G11+J11+M11 -> 80
B13: 2 | C13: ITB Review / FEED Verification
B14: 2.1 | C14: ITB Review & Interface work. | D14: Lot | E14: =OP1_CI!K24 -> 238 | F14: =OP1_CI!G24 -> 1 | G14: =OP1_CI!L24 -> 238 | H14: =OP1_CI!O24 -> 145.71429 | I14: =F14 -> 1 | J14: =OP1_CI!P24 -> 146 | N14: =G14+J14+M14 -> 384
B15: 2.2 | C15: 발주처 협의 (Technical Clarification) | D15: Lot | E15: - | F15: 1 | G15: =OP1_CI!L25 -> 280 | H15: - | I15: =F15 -> 1 | J15: =OP1_CI!P25 -> 171 | N15: =G15+J15+M15 -> 451
B16: 2.3 | C16: Feed Verification | D16: Lot | E16: - | F16: 1 | G16: =OP1_CI!L26 -> 280 | H16: - | I16: =F16 -> 1 | J16: =OP1_CI!P26 -> 171 | N16: =G16+J16+M16 -> 451
B17: 2.4 | C17: Early Work | D17: Lot | E17: - | F17: 1 | G17: =OP1_CI!L27 -> 0 | H17: - | I17: =F17 -> 1 | J17: =OP1_CI!P27 -> 0 | N17: =G17+J17+M17 -> 0
